Workbook

Sheet Inputs
B2: Project Cocoa: inputs ($mm, except per share)
B3: Source: SYNTHETIC DEMO DATA
B5: Company data | C5: Acquirer | D5: Target
B6: Ticker | C6: ACQ.DEMO | D6: TGT.DEMO
B7: Share price | C7: 85 | D7: 42
B8: Diluted shares (mm) | C8: 1200 | D8: 400
B9: NTM EPS (consensus) | C9: 4.5 | D9: 2.4
B10: Total debt | C10: 22000 | D10: 5000
B11: Cash | C11: 4000 | D11: 800
B12: LTM EBITDA | C12: 9800 | D12: 2050
B13: LTM revenue | C13: 52000 | D13: 12000
B14: Book equity | C14: 28000 | D14: 6500
B15: Market capitalisation | C15: =Inputs!$C$7*Inputs!$C$8 -> 102000 | D15: =Inputs!$D$7*Inputs!$D$8 -> 16800
B16: Net debt | C16: =Inputs!$C$10-Inputs!$C$11 -> 18000 | D16: =Inputs!$D$10-Inputs!$D$11 -> 4200
B17: P/E (NTM) | C17: =Inputs!$C$7/Inputs!$C$9 -> 18.888889 | D17: =Inputs!$D$7/Inputs!$D$9 -> 17.5
B18: NTM net income | C18: =Inputs!$C$9*Inputs!$C$8 -> 5400 | D18: =Inputs!$D$9*Inputs!$D$8 -> 960
B20: Deal assumptions
B21: Offer premium | C21: 0.3
B22: % of price paid in stock | C22: 0.5
B23: Pre-tax cost of new debt | C23: 0.06
B24: Pre-tax interest on cash | C24: 0.04
B25: Minimum cash retained by acquirer | C25: 2000
B26: Advisory fees (% of target EV) | C26: 0.012
B27: Financing fees (% of new debt) | C27: 0.02
B28: Financing fee amortisation (years) | C28: 7
B29: Intangible write-up (% of excess price) | C29: 0.25
B30: Intangible life (years) | C30: 15
B31: Run-rate pre-tax synergies | C31: 500
B32: Tax rate | C32: 0.23
... B34: Target EPS growth (years 2-3) | C34: 0.07
B35: Synergy phase-in (years 1-3) | C35: 0.4 | D35: 0.8 | E35: 1

Sheet Transaction
B2: Offer, sources & uses and purchase price allocation ($mm)
B4: Offer and funding | E4: Sources | F4: $mm
B5: Offer price per share | C5: =Inputs!$D$7*(1+Inputs!$C$21) -> 54.6 | E5: New acquirer shares | F5: =C12 -> 10920
B6: Equity purchase price | C6: =C5*Inputs!$D$8 -> 21840 | E6: New debt | F6: =C15 -> 9420.898
B7: (+) Target net debt assumed | C7: =Inputs!$D$16 -> 4200 | E7: Balance-sheet cash | F7: =C14 -> 2000
B8: Transaction enterprise value | C8: =C6+C7 -> 26040 | E8: Total sources | F8: =SUM(F5:F7) -> 22340.898
B9: Offer EV / LTM EBITDA | C9: =C8/Inputs!$D$12 -> 12.702439
B10: Offer P/E (NTM) | C10: =C5/Inputs!$D$9 -> 22.75 | E10: Uses | F10: $mm
B11: Cash consideration | C11: =C6*(1-Inputs!$C$22) -> 10920 | E11: Purchase of target equity | F11: =C6 -> 21840
B12: Stock consideration | C12: =C6*Inputs!$C$22 -> 10920 | E12: Advisory fees | F12: =C13 -> 312.48
B13: Advisory fees | C13: =Inputs!$C$26*C8 -> 312.48 | E13: Financing fees | F13: =C16 -> 188.41796
B14: Balance-sheet cash used | C14: =MIN(MAX(Inputs!$C$11-Inputs!$C$25,0),C11+C13) -> 2000 | E14: Total uses | F14: =SUM(F11:F13) -> 22340.898
B15: New debt raised (incl. financing fees) | C15: =(C11+C13-C14)/(1-Inputs!$C$27) -> 9420.898 | E15: Check (sources − uses) | F15: =F8-F14 -> 0
B16: Financing fees | C16: =C15*Inputs!$C$27 -> 188.41796
B17: New acquirer shares issued (mm) | C17: =C12/Inputs!$C$7 -> 128.47059
B18: Exchange ratio (stock component) | C18: =C5/Inputs!$C$7*Inputs!$C$22 -> 0.32117647
B20: Purchase price allocation
B21: Equity purchase price | C21: =C6 -> 21840
B22: (−) Target book equity | C22: =-Inputs!$D$14 -> -6500
B23: Excess purchase price | C23: =C21+C22 -> 15340
B24: Intangible write-up | C24: =C23*Inputs!$C$29 -> 3835
B25: Deferred tax liability on write-up | C25: =C24*Inputs!$C$32 -> 882.05
B26: Goodwill | C26: =C23-C24+C25 -> 12387.05
B27: Annual intangible amortisation | C27: =C24/Inputs!$C$30 -> 255.66667

Sheet Pro Forma
B2: Pro forma EPS: accretion / (dilution) ($mm, except per share)
C4: Year 1 | D4: Year 2 | E4: Year 3
B5: Acquirer standalone EPS | C5: =Inputs!$C$9*(1+Inputs!$C$33)^0 -> 4.5 | D5: =Inputs!$C$9*(1+Inputs!$C$33)^1 -> 4.815 | E5: =Inputs!$C$9*(1+Inputs!$C$33)^2 -> 5.15205
B6: Acquirer net income | C6: =C5*Inputs!$C$8 -> 5400 | D6: =D5*Inputs!$C$8 -> 5778 | E6: =E5*Inputs!$C$8 -> 6182.46
B7: Target net income | C7: =Inputs!$D$9*(1+Inputs!$C$34)^0*Inputs!$D$8 -> 960 | D7: =Inputs!$D$9*(1+Inputs!$C$34)^1*Inputs!$D$8 -> 1027.2 | E7: =Inputs!$D$9*(1+Inputs!$C$34)^2*Inputs!$D$8 -> 1099.104
B8: Synergies (pre-tax) | C8: =Inputs!$C$31*Inputs!$C$35 -> 200 | D8: =Inputs!$C$31*Inputs!$D$35 -> 400 | E8: =Inputs!$C$31*Inputs!$E$35 -> 500
B9: Interest on new debt | C9: =-Transaction!$C$15*Inputs!$C$23 -> -565.25388 | D9: =-Transaction!$C$15*Inputs!$C$23 -> -565.25388 | E9: =-Transaction!$C$15*Inputs!$C$23 -> -565.25388
B10: Interest forgone on cash | C10: =-Transaction!$C$14*Inputs!$C$24 -> -80 | D10: =-Transaction!$C$14*Inputs!$C$24 -> -80 | E10: =-Transaction!$C$14*Inputs!$C$24 -> -80
B11: Intangible amortisation | C11: =-Transaction!$C$27 -> -255.66667 | D11: =-Transaction!$C$27 -> -255.66667 | E11: =-Transaction!$C$27 -> -255.66667
B12: Financing fee amortisation | C12: =-Transaction!$C$16/Inputs!$C$28 -> -26.916851 | D12: =-Transaction!$C$16/Inputs!$C$28 -> -26.916851 | E12: =-Transaction!$C$16/Inputs!$C$28 -> -26.916851
B13: Tax on adjustments | C13: =-SUM(C8:C12)*Inputs!$C$32 -> 167.4026 | D13: =-SUM(D8:D12)*Inputs!$C$32 -> 121.4026 | E13: =-SUM(E8:E12)*Inputs!$C$32 -> 98.402601
B14: Pro forma net income | C14: =SUM(C6:C13) -> 5799.5652 | D14: =SUM(D6:D13) -> 6398.7652 | E14: =SUM(E6:E13) -> 6952.1292
B15: Acquirer shares | C15: =Inputs!$C$8 -> 1200 | D15: =Inputs!$C$8 -> 1200 | E15: =Inputs!$C$8 -> 1200
B16: New shares issued | C16: =Transaction!$C$17 -> 128.47059 | D16: =Transaction!$C$17 -> 128.47059 | E16: =Transaction!$C$17 -> 128.47059
B17: Pro forma shares | C17: =C15+C16 -> 1328.4706 | D17: =D15+D16 -> 1328.4706 | E17: =E15+E16 -> 1328.4706
B18: Pro forma EPS | C18: =C14/C17 -> 4.3655955 | D18: =D14/D17 -> 4.8166405 | E18: =E14/E17 -> 5.2331826
B19: Accretion / (dilution) | C19: =C18/C5-1 -> -0.029867669 | D19: =D18/D5-1 -> 0.00034070098 | E19: =E18/E5-1 -> 0.01574764
B20: Cash EPS (ex. amortisation) | C20: =(C14-C11*(1-Inputs!$C$32))/C17 -> 4.5137834 | D20: =(D14-D11*(1-Inputs!$C$32))/D17 -> 4.9648284 | E20: =(E14-E11*(1-Inputs!$C$32))/E17 -> 5.3813706
B21: Cash EPS accretion / (dilution) | C21: =C20/C5-1 -> 0.0030629862 | D21: =D20/D5-1 -> 0.031117015 | E21: =E20/E5-1 -> 0.04451055
B22: Breakeven pre-tax synergies | C22: =MAX(0,(C5*C17-(C14-C8*(1-Inputs!$C$32)))/(1-Inputs!$C$32)) -> 431.88629 | D22: =MAX(0,(D5*D17-(D14-D8*(1-Inputs!$C$32)))/(1-Inputs!$C$32)) -> 397.16971 | E22: =MAX(0,(E5*E17-(E14-E8*(1-Inputs!$C$32)))/(1-Inputs!$C$32)) -> 360.02297

Sheet Sensitivity
B2: Year 2 EPS accretion / (dilution): every cell is a full merger-model formula
B4: Offer premium (rows) × % stock (columns)
B5: ↓ rows / % stock → | C5: 0 | D5: 0.25 | E5: 0.5 | F5: 0.75 | G5: 1
B6: 0.15 | C6: =((Inputs!$C$9*(1+Inputs!$C$33)^1)*Inputs!$C$8+Inputs!$D$9*(1+Inputs!$C$34)^1*Inputs!$D$8+(Inputs!$C$31*Inputs!$D$35-(((((Inputs!$D$7*(1+$B$6))*Inputs!$D$8)*(1-C$5))+(Inputs!$C$26*(((Inputs!$D$7*(1+$B$6))*Inputs!$D$8)+Inputs!$D$16))-MIN(MAX(Inputs!$C$11-Inputs!$C$25,0),(((Inputs!$D$7*(1+$B$6))*Inputs!$D$8)*(1-C$5))+(Inputs!$C$26*(((Inputs!$D$7*(1+$B$6))*Inputs!$D$8)+Inputs!$D$16))))/(1-Inputs!$C$27))*Inputs!$C$23-MIN(MAX(Inputs!$C$11-Inputs!$C$25,0),(((Inputs!$D$7*(1+$B$6))*Inputs!$D$8)*(1-C$5))+(Inputs!$C$26*(((Inputs!$D$7*(1+$B$6))*Inputs!$D$8)+Inputs!$D$16)))*Inputs!$C$24-(Inputs!$C$29*(((Inputs!$D$7*(1+$B$6))*Inputs!$D$8)-Inputs!$D$14))/Inputs!$C$30-(((((Inputs!$D$7*(1+$B$6))*Inputs!$D$8)*(1-C$5))+(Inputs!$C$26*(((Inputs!$D$7*(1+$B$6))*Inputs!$D$8)+Inputs!$D$16))-MIN(MAX(Inputs!$C$11-Inputs!$C$25,0),(((Inputs!$D$7*(1+$B$6))*Inputs!$D$8)*(1-C$5))+(Inputs!$C$26*(((Inputs!$D$7*(1+$B$6))*Inputs!$D$8)+Inputs!$D$16))))/(1-Inputs!$C$27))*Inputs!$C$27/Inputs!$C$28)*(1-Inputs!$C$32))/(Inputs!$C$8+(((Inputs!$D$7*(1+$B$6))*Inputs!$D$8)*C$5/Inputs!$C$7))/(Inputs!$C$9*(1+Inputs!$C$33)^1)-1 -> 0.041492134 | D6: =((Inputs!$C$9*(1+Inputs!$C$33)^1)*Inputs!$C$8+Inputs!$D$9*(1+Inputs!$C$34)^1*Inputs!$D$8+(Inputs!$C$31*Inputs!$D$35-(((((Inputs!$D$7*(1+$B$6))*Inputs!$D$8)*(1-D$5))+(Inputs!$C$26*(((Inputs!$D$7*(1+$B$6))*Inputs!$D$8)+Inputs!$D$16))-MIN(MAX(Inputs!$C$11-Inputs!$C$25,0),(((Inputs!$D$7*(1+$B$6))*Inputs!$D$8)*(1-D$5))+(Inputs!$C$26*(((Inputs!$D$7*(1+$B$6))*Inputs!$D$8)+Inputs!$D$16))))/(1-Inputs!$C$27))*Inputs!$C$23-MIN(MAX(Inputs!$C$11-Inputs!$C$25,0),(((Inputs!$D$7*(1+$B$6))*Inputs!$D$8)*(1-D$5))+(Inputs!$C$26*(((Inputs!$D$7*(1+$B$6))*Inputs!$D$8)+Inputs!$D$16)))*Inputs!$C$24-(Inputs!$C$29*(((Inputs!$D$7*(1+$B$6))*Inputs!$D$8)-Inputs!$D$14))/Inputs!$C$30-(((((Inputs!$D$7*(1+$B$6))*Inputs!$D$8)*(1-D$5))+(Inputs!$C$26*(((Inputs!$D$7*(1+$B$6))*Inputs!$D$8)+Inputs!$D$16))-MIN(MAX(Inputs!$C$11-Inputs!$C$25,0),(((Inputs!$D$7*(1+$B$6))*Inputs!$D$8)*(1-D$5))+(Inputs!$C$26*(((Inputs!$D$7*(1+$B$6))*Inputs!$D$8)+Inputs!$D$16))))/(1-Inputs!$C$27))*Inputs!$C$27/Inputs!$C$28)*(1-Inputs!$C$32))/(Inputs!$C$8+(((Inputs!$D$7*(1+$B$6))*Inputs!$D$8)*D$5/Inputs!$C$7))/(Inputs!$C$9*(1+Inputs!$C$33)^1)-1 -> 0.033822284 | E6: =((Inputs!$C$9*(1+Inputs!$C$33)^1)*Inputs!$C$8+Inputs!$D$9*(1+Inputs!$C$34)^1*Inputs!$D$8+(Inputs!$C$31*Inputs!$D$35-(((((Inputs!$D$7*(1+$B$6))*Inputs!$D$8)*(1-E$5))+(Inputs!$C$26*(((Inputs!$D$7*(1+$B$6))*Inputs!$D$8)+Inputs!$D$16))-MIN(MAX(Inputs!$C$11-Inputs!$C$25,0),(((Inputs!$D$7*(1+$B$6))*Inputs!$D$8)*(1-E$5))+(Inputs!$C$26*(((Inputs!$D$7*(1+$B$6))*Inputs!$D$8)+Inputs!$D$16))))/(1-Inputs!$C$27))*Inputs!$C$23-MIN(MAX(Inputs!$C$11-Inputs!$C$25,0),(((Inputs!$D$7*(1+$B$6))*Inputs!$D$8)*(1-E$5))+(Inputs!$C$26*(((Inputs!$D$7*(1+$B$6))*Inputs!$D$8)+Inputs!$D$16)))*Inputs!$C$24-(Inputs!$C$29*(((Inputs!$D$7*(1+$B$6))*Inputs!$D$8)-Inputs!$D$14))/Inputs!$C$30-(((((Inputs!$D$7*(1+$B$6))*Inputs!$D$8)*(1-E$5))+(Inputs!$C$26*(((Inputs!$D$7*(1+$B$6))*Inputs!$D$8)+Inputs!$D$16))-MIN(MAX(Inputs!$C$11-Inputs!$C$25,0),(((Inputs!$D$7*(1+$B$6))*Inputs!$D$8)*(1-E$5))+(Inputs!$C$26*(((Inputs!$D$7*(1+$B$6))*Inputs!$D$8)+Inputs!$D$16))))/(1-Inputs!$C$27))*Inputs!$C$27/Inputs!$C$28)*(1-Inputs!$C$32))/(Inputs!$C$8+(((Inputs!$D$7*(1+$B$6))*Inputs!$D$8)*E$5/Inputs!$C$7))/(Inputs!$C$9*(1+Inputs!$C$33)^1)-1 -> 0.026815973 | F6: =((Inputs!$C$9*(1+Inputs!$C$33)^1)*Inputs!$C$8+Inputs!$D$9*(1+Inputs!$C$34)^1*Inputs!$D$8+(Inputs!$C$31*Inputs!$D$35-(((((Inputs!$D$7*(1+$B$6))*Inputs!$D$8)*(1-F$5))+(Inputs!$C$26*(((Inputs!$D$7*(1+$B$6))*Inputs!$D$8)+Inputs!$D$16))-MIN(MAX(Inputs!$C$11-Inputs!$C$25,0),(((Inputs!$D$7*(1+$B$6))*Inputs!$D$8)*(1-F$5))+(Inputs!$C$26*(((Inputs!$D$7*(1+$B$6))*Inputs!$D$8)+Inputs!$D$16))))/(1-Inputs!$C$27))*Inputs!$C$23-MIN(MAX(Inputs!$C$11-Inputs!$C$25,0),(((Inputs!$D$7*(1+$B$6))*Inputs!$D$8)*(1-F$5))+(Inputs!$C$26*(((Inputs!$D$7*(1+$B$6))*Inputs!$D$8)+Inputs!$D$16)))*Inputs!$C$24-(Inputs!$C$29*(((Inputs!$D$7*(1+$B$6))*Inputs!$D$8)-Inputs!$D$14))/Inputs!$C$30-(((((Inputs!$D$7*(1+$B$6))*Inputs!$D$8)*(1-F$5))+(Inputs!$C$26*(((Inputs!$D$7*(1+$B$6))*Inputs!$D$8)+Inputs!$D$16))-MIN(MAX(Inputs!$C$11-Inputs!$C$25,0),(((Inputs!$D$7*(1+$B$6))*Inputs!$D$8)*(1-F$5))+(Inputs!$C$26*(((Inputs!$D$7*(1+$B$6))*Inputs!$D$8)+Inputs!$D$16))))/(1-Inputs!$C$27))*Inputs!$C$27/Inputs!$C$28)*(1-Inputs!$C$32))/(Inputs!$C$8+(((Inputs!$D$7*(1+$B$6))*Inputs!$D$8)*F$5/Inputs!$C$7))/(Inputs!$C$9*(1+Inputs!$C$33)^1)-1 -> 0.020390664 | G6: =((Inputs!$C$9*(1+Inputs!$C$33)^1)*Inputs!$C$8+Inputs!$D$9*(1+Inputs!$C$34)^1*Inputs!$D$8+(Inputs!$C$31*Inputs!$D$35-(((((Inputs!$D$7*(1+$B$6))*Inputs!$D$8)*(1-G$5))+(Inputs!$C$26*(((Inputs!$D$7*(1+$B$6))*Inputs!$D$8)+Inputs!$D$16))-MIN(MAX(Inputs!$C$11-Inputs!$C$25,0),(((Inputs!$D$7*(1+$B$6))*Inputs!$D$8)*(1-G$5))+(Inputs!$C$26*(((Inputs!$D$7*(1+$B$6))*Inputs!$D$8)+Inputs!$D$16))))/(1-Inputs!$C$27))*Inputs!$C$23-MIN(MAX(Inputs!$C$11-Inputs!$C$25,0),(((Inputs!$D$7*(1+$B$6))*Inputs!$D$8)*(1-G$5))+(Inputs!$C$26*(((Inputs!$D$7*(1+$B$6))*Inputs!$D$8)+Inputs!$D$16)))*Inputs!$C$24-(Inputs!$C$29*(((Inputs!$D$7*(1+$B$6))*Inputs!$D$8)-Inputs!$D$14))/Inputs!$C$30-(((((Inputs!$D$7*(1+$B$6))*Inputs!$D$8)*(1-G$5))+(Inputs!$C$26*(((Inputs!$D$7*(1+$B$6))*Inputs!$D$8)+Inputs!$D$16))-MIN(MAX(Inputs!$C$11-Inputs!$C$25,0),(((Inputs!$D$7*(1+$B$6))*Inputs!$D$8)*(1-G$5))+(Inputs!$C$26*(((Inputs!$D$7*(1+$B$6))*Inputs!$D$8)+Inputs!$D$16))))/(1-Inputs!$C$27))*Inputs!$C$27/Inputs!$C$28)*(1-Inputs!$C$32))/(Inputs!$C$8+(((Inputs!$D$7*(1+$B$6))*Inputs!$D$8)*G$5/Inputs!$C$7))/(Inputs!$C$9*(1+Inputs!$C$33)^1)-1 -> 0.0098309601
B7: 0.225 | C7: =((Inputs!$C$9*(1+Inputs!$C$33)^1)*Inputs!$C$8+Inputs!$D$9*(1+Inputs!$C$34)^1*Inputs!$D$8+(Inputs!$C$31*Inputs!$D$35-(((((Inputs!$D$7*(1+$B$7))*Inputs!$D$8)*(1-C$5))+(Inputs!$C$26*(((Inputs!$D$7*(1+$B$7))*Inputs!$D$8)+Inputs!$D$16))-MIN(MAX(Inputs!$C$11-Inputs!$C$25,0),(((Inputs!$D$7*(1+$B$7))*Inputs!$D$8)*(1-C$5))+(Inputs!$C$26*(((Inputs!$D$7*(1+$B$7))*Inputs!$D$8)+Inputs!$D$16))))/(1-Inputs!$C$27))*Inputs!$C$23-MIN(MAX(Inputs!$C$11-Inputs!$C$25,0),(((Inputs!$D$7*(1+$B$7))*Inputs!$D$8)*(1-C$5))+(Inputs!$C$26*(((Inputs!$D$7*(1+$B$7))*Inputs!$D$8)+Inputs!$D$16)))*Inputs!$C$24-(Inputs!$C$29*(((Inputs!$D$7*(1+$B$7))*Inputs!$D$8)-Inputs!$D$14))/Inputs!$C$30-(((((Inputs!$D$7*(1+$B$7))*Inputs!$D$8)*(1-C$5))+(Inputs!$C$26*(((Inputs!$D$7*(1+$B$7))*Inputs!$D$8)+Inputs!$D$16))-MIN(MAX(Inputs!$C$11-Inputs!$C$25,0),(((Inputs!$D$7*(1+$B$7))*Inputs!$D$8)*(1-C$5))+(Inputs!$C$26*(((Inputs!$D$7*(1+$B$7))*Inputs!$D$8)+Inputs!$D$16))))/(1-Inputs!$C$27))*Inputs!$C$27/Inputs!$C$28)*(1-Inputs!$C$32))/(Inputs!$C$8+(((Inputs!$D$7*(1+$B$7))*Inputs!$D$8)*C$5/Inputs!$C$7))/(Inputs!$C$9*(1+Inputs!$C$33)^1)-1 -> 0.027794433 | D7: =((Inputs!$C$9*(1+Inputs!$C$33)^1)*Inputs!$C$8+Inputs!$D$9*(1+Inputs!$C$34)^1*Inputs!$D$8+(Inputs!$C$31*Inputs!$D$35-(((((Inputs!$D$7*(1+$B$7))*Inputs!$D$8)*(1-D$5))+(Inputs!$C$26*(((Inputs!$D$7*(1+$B$7))*Inputs!$D$8)+Inputs!$D$16))-MIN(MAX(Inputs!$C$11-Inputs!$C$25,0),(((Inputs!$D$7*(1+$B$7))*Inputs!$D$8)*(1-D$5))+(Inputs!$C$26*(((Inputs!$D$7*(1+$B$7))*Inputs!$D$8)+Inputs!$D$16))))/(1-Inputs!$C$27))*Inputs!$C$23-MIN(MAX(Inputs!$C$11-Inputs!$C$25,0),(((Inputs!$D$7*(1+$B$7))*Inputs!$D$8)*(1-D$5))+(Inputs!$C$26*(((Inputs!$D$7*(1+$B$7))*Inputs!$D$8)+Inputs!$D$16)))*Inputs!$C$24-(Inputs!$C$29*(((Inputs!$D$7*(1+$B$7))*Inputs!$D$8)-Inputs!$D$14))/Inputs!$C$30-(((((Inputs!$D$7*(1+$B$7))*Inputs!$D$8)*(1-D$5))+(Inputs!$C$26*(((Inputs!$D$7*(1+$B$7))*Inputs!$D$8)+Inputs!$D$16))-MIN(MAX(Inputs!$C$11-Inputs!$C$25,0),(((Inputs!$D$7*(1+$B$7))*Inputs!$D$8)*(1-D$5))+(Inputs!$C$26*(((Inputs!$D$7*(1+$B$7))*Inputs!$D$8)+Inputs!$D$16))))/(1-Inputs!$C$27))*Inputs!$C$27/Inputs!$C$28)*(1-Inputs!$C$32))/(Inputs!$C$8+(((Inputs!$D$7*(1+$B$7))*Inputs!$D$8)*D$5/Inputs!$C$7))/(Inputs!$C$9*(1+Inputs!$C$33)^1)-1 -> 0.020306145 | E7: =((Inputs!$C$9*(1+Inputs!$C$33)^1)*Inputs!$C$8+Inputs!$D$9*(1+Inputs!$C$34)^1*Inputs!$D$8+(Inputs!$C$31*Inputs!$D$35-(((((Inputs!$D$7*(1+$B$7))*Inputs!$D$8)*(1-E$5))+(Inputs!$C$26*(((Inputs!$D$7*(1+$B$7))*Inputs!$D$8)+Inputs!$D$16))-MIN(MAX(Inputs!$C$11-Inputs!$C$25,0),(((Inputs!$D$7*(1+$B$7))*Inputs!$D$8)*(1-E$5))+(Inputs!$C$26*(((Inputs!$D$7*(1+$B$7))*Inputs!$D$8)+Inputs!$D$16))))/(1-Inputs!$C$27))*Inputs!$C$23-MIN(MAX(Inputs!$C$11-Inputs!$C$25,0),(((Inputs!$D$7*(1+$B$7))*Inputs!$D$8)*(1-E$5))+(Inputs!$C$26*(((Inputs!$D$7*(1+$B$7))*Inputs!$D$8)+Inputs!$D$16)))*Inputs!$C$24-(Inputs!$C$29*(((Inputs!$D$7*(1+$B$7))*Inputs!$D$8)-Inputs!$D$14))/Inputs!$C$30-(((((Inputs!$D$7*(1+$B$7))*Inputs!$D$8)*(1-E$5))+(Inputs!$C$26*(((Inputs!$D$7*(1+$B$7))*Inputs!$D$8)+Inputs!$D$16))-MIN(MAX(Inputs!$C$11-Inputs!$C$25,0),(((Inputs!$D$7*(1+$B$7))*Inputs!$D$8)*(1-E$5))+(Inputs!$C$26*(((Inputs!$D$7*(1+$B$7))*Inputs!$D$8)+Inputs!$D$16))))/(1-Inputs!$C$27))*Inputs!$C$27/Inputs!$C$28)*(1-Inputs!$C$32))/(Inputs!$C$8+(((Inputs!$D$7*(1+$B$7))*Inputs!$D$8)*E$5/Inputs!$C$7))/(Inputs!$C$9*(1+Inputs!$C$33)^1)-1 -> 0.013504067 | F7: =((Inputs!$C$9*(1+Inputs!$C$33)^1)*Inputs!$C$8+Inputs!$D$9*(1+Inputs!$C$34)^1*Inputs!$D$8+(Inputs!$C$31*Inputs!$D$35-(((((Inputs!$D$7*(1+$B$7))*Inputs!$D$8)*(1-F$5))+(Inputs!$C$26*(((Inputs!$D$7*(1+$B$7))*Inputs!$D$8)+Inputs!$D$16))-MIN(MAX(Inputs!$C$11-Inputs!$C$25,0),(((Inputs!$D$7*(1+$B$7))*Inputs!$D$8)*(1-F$5))+(Inputs!$C$26*(((Inputs!$D$7*(1+$B$7))*Inputs!$D$8)+Inputs!$D$16))))/(1-Inputs!$C$27))*Inputs!$C$23-MIN(MAX(Inputs!$C$11-Inputs!$C$25,0),(((Inputs!$D$7*(1+$B$7))*Inputs!$D$8)*(1-F$5))+(Inputs!$C$26*(((Inputs!$D$7*(1+$B$7))*Inputs!$D$8)+Inputs!$D$16)))*Inputs!$C$24-(Inputs!$C$29*(((Inputs!$D$7*(1+$B$7))*Inputs!$D$8)-Inputs!$D$14))/Inputs!$C$30-(((((Inputs!$D$7*(1+$B$7))*Inputs!$D$8)*(1-F$5))+(Inputs!$C$26*(((Inputs!$D$7*(1+$B$7))*Inputs!$D$8)+Inputs!$D$16))-MIN(MAX(Inputs!$C$11-Inputs!$C$25,0),(((Inputs!$D$7*(1+$B$7))*Inputs!$D$8)*(1-F$5))+(Inputs!$C$26*(((Inputs!$D$7*(1+$B$7))*Inputs!$D$8)+Inputs!$D$16))))/(1-Inputs!$C$27))*Inputs!$C$27/Inputs!$C$28)*(1-Inputs!$C$32))/(Inputs!$C$8+(((Inputs!$D$7*(1+$B$7))*Inputs!$D$8)*F$5/Inputs!$C$7))/(Inputs!$C$9*(1+Inputs!$C$33)^1)-1 -> 0.0072980075 | G7: =((Inputs!$C$9*(1+Inputs!$C$33)^1)*Inputs!$C$8+Inputs!$D$9*(1+Inputs!$C$34)^1*Inputs!$D$8+(Inputs!$C$31*Inputs!$D$35-(((((Inputs!$D$7*(1+$B$7))*Inputs!$D$8)*(1-G$5))+(Inputs!$C$26*(((Inputs!$D$7*(1+$B$7))*Inputs!$D$8)+Inputs!$D$16))-MIN(MAX(Inputs!$C$11-Inputs!$C$25,0),(((Inputs!$D$7*(1+$B$7))*Inputs!$D$8)*(1-G$5))+(Inputs!$C$26*(((Inputs!$D$7*(1+$B$7))*Inputs!$D$8)+Inputs!$D$16))))/(1-Inputs!$C$27))*Inputs!$C$23-MIN(MAX(Inputs!$C$11-Inputs!$C$25,0),(((Inputs!$D$7*(1+$B$7))*Inputs!$D$8)*(1-G$5))+(Inputs!$C$26*(((Inputs!$D$7*(1+$B$7))*Inputs!$D$8)+Inputs!$D$16)))*Inputs!$C$24-(Inputs!$C$29*(((Inputs!$D$7*(1+$B$7))*Inputs!$D$8)-Inputs!$D$14))/Inputs!$C$30-(((((Inputs!$D$7*(1+$B$7))*Inputs!$D$8)*(1-G$5))+(Inputs!$C$26*(((Inputs!$D$7*(1+$B$7))*Inputs!$D$8)+Inputs!$D$16))-MIN(MAX(Inputs!$C$11-Inputs!$C$25,0),(((Inputs!$D$7*(1+$B$7))*Inputs!$D$8)*(1-G$5))+(Inputs!$C$26*(((Inputs!$D$7*(1+$B$7))*Inputs!$D$8)+Inputs!$D$16))))/(1-Inputs!$C$27))*Inputs!$C$27/Inputs!$C$28)*(1-Inputs!$C$32))/(Inputs!$C$8+(((Inputs!$D$7*(1+$B$7))*Inputs!$D$8)*G$5/Inputs!$C$7))/(Inputs!$C$9*(1+Inputs!$C$33)^1)-1 -> -0.0029448576
B8: 0.3 | C8: =((Inputs!$C$9*(1+Inputs!$C$33)^1)*Inputs!$C$8+Inputs!$D$9*(1+Inputs!$C$34)^1*Inputs!$D$8+(Inputs!$C$31*Inputs!$D$35-(((((Inputs!$D$7*(1+$B$8))*Inputs!$D$8)*(1-C$5))+(Inputs!$C$26*(((Inputs!$D$7*(1+$B$8))*Inputs!$D$8)+Inputs!$D$16))-MIN(MAX(Inputs!$C$11-Inputs!$C$25,0),(((Inputs!$D$7*(1+$B$8))*Inputs!$D$8)*(1-C$5))+(Inputs!$C$26*(((Inputs!$D$7*(1+$B$8))*Inputs!$D$8)+Inputs!$D$16))))/(1-Inputs!$C$27))*Inputs!$C$23-MIN(MAX(Inputs!$C$11-Inputs!$C$25,0),(((Inputs!$D$7*(1+$B$8))*Inputs!$D$8)*(1-C$5))+(Inputs!$C$26*(((Inputs!$D$7*(1+$B$8))*Inputs!$D$8)+Inputs!$D$16)))*Inputs!$C$24-(Inputs!$C$29*(((Inputs!$D$7*(1+$B$8))*Inputs!$D$8)-Inputs!$D$14))/Inputs!$C$30-(((((Inputs!$D$7*(1+$B$8))*Inputs!$D$8)*(1-C$5))+(Inputs!$C$26*(((Inputs!$D$7*(1+$B$8))*Inputs!$D$8)+Inputs!$D$16))-MIN(MAX(Inputs!$C$11-Inputs!$C$25,0),(((Inputs!$D$7*(1+$B$8))*Inputs!$D$8)*(1-C$5))+(Inputs!$C$26*(((Inputs!$D$7*(1+$B$8))*Inputs!$D$8)+Inputs!$D$16))))/(1-Inputs!$C$27))*Inputs!$C$27/Inputs!$C$28)*(1-Inputs!$C$32))/(Inputs!$C$8+(((Inputs!$D$7*(1+$B$8))*Inputs!$D$8)*C$5/Inputs!$C$7))/(Inputs!$C$9*(1+Inputs!$C$33)^1)-1 -> 0.014096732 | D8: =((Inputs!$C$9*(1+Inputs!$C$33)^1)*Inputs!$C$8+Inputs!$D$9*(1+Inputs!$C$34)^1*Inputs!$D$8+(Inputs!$C$31*Inputs!$D$35-(((((Inputs!$D$7*(1+$B$8))*Inputs!$D$8)*(1-D$5))+(Inputs!$C$26*(((Inputs!$D$7*(1+$B$8))*Inputs!$D$8)+Inputs!$D$16))-MIN(MAX(Inputs!$C$11-Inputs!$C$25,0),(((Inputs!$D$7*(1+$B$8))*Inputs!$D$8)*(1-D$5))+(Inputs!$C$26*(((Inputs!$D$7*(1+$B$8))*Inputs!$D$8)+Inputs!$D$16))))/(1-Inputs!$C$27))*Inputs!$C$23-MIN(MAX(Inputs!$C$11-Inputs!$C$25,0),(((Inputs!$D$7*(1+$B$8))*Inputs!$D$8)*(1-D$5))+(Inputs!$C$26*(((Inputs!$D$7*(1+$B$8))*Inputs!$D$8)+Inputs!$D$16)))*Inputs!$C$24-(Inputs!$C$29*(((Inputs!$D$7*(1+$B$8))*Inputs!$D$8)-Inputs!$D$14))/Inputs!$C$30-(((((Inputs!$D$7*(1+$B$8))*Inputs!$D$8)*(1-D$5))+(Inputs!$C$26*(((Inputs!$D$7*(1+$B$8))*Inputs!$D$8)+Inputs!$D$16))-MIN(MAX(Inputs!$C$11-Inputs!$C$25,0),(((Inputs!$D$7*(1+$B$8))*Inputs!$D$8)*(1-D$5))+(Inputs!$C$26*(((Inputs!$D$7*(1+$B$8))*Inputs!$D$8)+Inputs!$D$16))))/(1-Inputs!$C$27))*Inputs!$C$27/Inputs!$C$28)*(1-Inputs!$C$32))/(Inputs!$C$8+(((Inputs!$D$7*(1+$B$8))*Inputs!$D$8)*D$5/Inputs!$C$7))/(Inputs!$C$9*(1+Inputs!$C$33)^1)-1 -> 0.0068692474 | E8: =((Inputs!$C$9*(1+Inputs!$C$33)^1)*Inputs!$C$8+Inputs!$D$9*(1+Inputs!$C$34)^1*Inputs!$D$8+(Inputs!$C$31*Inputs!$D$35-(((((Inputs!$D$7*(1+$B$8))*Inputs!$D$8)*(1-E$5))+(Inputs!$C$26*(((Inputs!$D$7*(1+$B$8))*Inputs!$D$8)+Inputs!$D$16))-MIN(MAX(Inputs!$C$11-Inputs!$C$25,0),(((Inputs!$D$7*(1+$B$8))*Inputs!$D$8)*(1-E$5))+(Inputs!$C$26*(((Inputs!$D$7*(1+$B$8))*Inputs!$D$8)+Inputs!$D$16))))/(1-Inputs!$C$27))*Inputs!$C$23-MIN(MAX(Inputs!$C$11-Inputs!$C$25,0),(((Inputs!$D$7*(1+$B$8))*Inputs!$D$8)*(1-E$5))+(Inputs!$C$26*(((Inputs!$D$7*(1+$B$8))*Inputs!$D$8)+Inputs!$D$16)))*Inputs!$C$24-(Inputs!$C$29*(((Inputs!$D$7*(1+$B$8))*Inputs!$D$8)-Inputs!$D$14))/Inputs!$C$30-(((((Inputs!$D$7*(1+$B$8))*Inputs!$D$8)*(1-E$5))+(Inputs!$C$26*(((Inputs!$D$7*(1+$B$8))*Inputs!$D$8)+Inputs!$D$16))-MIN(MAX(Inputs!$C$11-Inputs!$C$25,0),(((Inputs!$D$7*(1+$B$8))*Inputs!$D$8)*(1-E$5))+(Inputs!$C$26*(((Inputs!$D$7*(1+$B$8))*Inputs!$D$8)+Inputs!$D$16))))/(1-Inputs!$C$27))*Inputs!$C$27/Inputs!$C$28)*(1-Inputs!$C$32))/(Inputs!$C$8+(((Inputs!$D$7*(1+$B$8))*Inputs!$D$8)*E$5/Inputs!$C$7))/(Inputs!$C$9*(1+Inputs!$C$33)^1)-1 -> 0.00034070098 | F8: =((Inputs!$C$9*(1+Inputs!$C$33)^1)*Inputs!$C$8+Inputs!$D$9*(1+Inputs!$C$34)^1*Inputs!$D$8+(Inputs!$C$31*Inputs!$D$35-(((((Inputs!$D$7*(1+$B$8))*Inputs!$D$8)*(1-F$5))+(Inputs!$C$26*(((Inputs!$D$7*(1+$B$8))*Inputs!$D$8)+Inputs!$D$16))-MIN(MAX(Inputs!$C$11-Inputs!$C$25,0),(((Inputs!$D$7*(1+$B$8))*Inputs!$D$8)*(1-F$5))+(Inputs!$C$26*(((Inputs!$D$7*(1+$B$8))*Inputs!$D$8)+Inputs!$D$16))))/(1-Inputs!$C$27))*Inputs!$C$23-MIN(MAX(Inputs!$C$11-Inputs!$C$25,0),(((Inputs!$D$7*(1+$B$8))*Inputs!$D$8)*(1-F$5))+(Inputs!$C$26*(((Inputs!$D$7*(1+$B$8))*Inputs!$D$8)+Inputs!$D$16)))*Inputs!$C$24-(Inputs!$C$29*(((Inputs!$D$7*(1+$B$8))*Inputs!$D$8)-Inputs!$D$14))/Inputs!$C$30-(((((Inputs!$D$7*(1+$B$8))*Inputs!$D$8)*(1-F$5))+(Inputs!$C$26*(((Inputs!$D$7*(1+$B$8))*Inputs!$D$8)+Inputs!$D$16))-MIN(MAX(Inputs!$C$11-Inputs!$C$25,0),(((Inputs!$D$7*(1+$B$8))*Inputs!$D$8)*(1-F$5))+(Inputs!$C$26*(((Inputs!$D$7*(1+$B$8))*Inputs!$D$8)+Inputs!$D$16))))/(1-Inputs!$C$27))*Inputs!$C$27/Inputs!$C$28)*(1-Inputs!$C$32))/(Inputs!$C$8+(((Inputs!$D$7*(1+$B$8))*Inputs!$D$8)*F$5/Inputs!$C$7))/(Inputs!$C$9*(1+Inputs!$C$33)^1)-1 -> -0.0055856177 | G8: =((Inputs!$C$9*(1+Inputs!$C$33)^1)*Inputs!$C$8+Inputs!$D$9*(1+Inputs!$C$34)^1*Inputs!$D$8+(Inputs!$C$31*Inputs!$D$35-(((((Inputs!$D$7*(1+$B$8))*Inputs!$D$8)*(1-G$5))+(Inputs!$C$26*(((Inputs!$D$7*(1+$B$8))*Inputs!$D$8)+Inputs!$D$16))-MIN(MAX(Inputs!$C$11-Inputs!$C$25,0),(((Inputs!$D$7*(1+$B$8))*Inputs!$D$8)*(1-G$5))+(Inputs!$C$26*(((Inputs!$D$7*(1+$B$8))*Inputs!$D$8)+Inputs!$D$16))))/(1-Inputs!$C$27))*Inputs!$C$23-MIN(MAX(Inputs!$C$11-Inputs!$C$25,0),(((Inputs!$D$7*(1+$B$8))*Inputs!$D$8)*(1-G$5))+(Inputs!$C$26*(((Inputs!$D$7*(1+$B$8))*Inputs!$D$8)+Inputs!$D$16)))*Inputs!$C$24-(Inputs!$C$29*(((Inputs!$D$7*(1+$B$8))*Inputs!$D$8)-Inputs!$D$14))/Inputs!$C$30-(((((Inputs!$D$7*(1+$B$8))*Inputs!$D$8)*(1-G$5))+(Inputs!$C$26*(((Inputs!$D$7*(1+$B$8))*Inputs!$D$8)+Inputs!$D$16))-MIN(MAX(Inputs!$C$11-Inputs!$C$25,0),(((Inputs!$D$7*(1+$B$8))*Inputs!$D$8)*(1-G$5))+(Inputs!$C$26*(((Inputs!$D$7*(1+$B$8))*Inputs!$D$8)+Inputs!$D$16))))/(1-Inputs!$C$27))*Inputs!$C$27/Inputs!$C$28)*(1-Inputs!$C$32))/(Inputs!$C$8+(((Inputs!$D$7*(1+$B$8))*Inputs!$D$8)*G$5/Inputs!$C$7))/(Inputs!$C$9*(1+Inputs!$C$33)^1)-1 -> -0.015460702
B9: 0.375 | C9: =((Inputs!$C$9*(1+Inputs!$C$33)^1)*Inputs!$C$8+Inputs!$D$9*(1+Inputs!$C$34)^1*Inputs!$D$8+(Inputs!$C$31*Inputs!$D$35-(((((Inputs!$D$7*(1+$B$9))*Inputs!$D$8)*(1-C$5))+(Inputs!$C$26*(((Inputs!$D$7*(1+$B$9))*Inputs!$D$8)+Inputs!$D$16))-MIN(MAX(Inputs!$C$11-Inputs!$C$25,0),(((Inputs!$D$7*(1+$B$9))*Inputs!$D$8)*(1-C$5))+(Inputs!$C$26*(((Inputs!$D$7*(1+$B$9))*Inputs!$D$8)+Inputs!$D$16))))/(1-Inputs!$C$27))*Inputs!$C$23-MIN(MAX(Inputs!$C$11-Inputs!$C$25,0),(((Inputs!$D$7*(1+$B$9))*Inputs!$D$8)*(1-C$5))+(Inputs!$C$26*(((Inputs!$D$7*(1+$B$9))*Inputs!$D$8)+Inputs!$D$16)))*Inputs!$C$24-(Inputs!$C$29*(((Inputs!$D$7*(1+$B$9))*Inputs!$D$8)-Inputs!$D$14))/Inputs!$C$30-(((((Inputs!$D$7*(1+$B$9))*Inputs!$D$8)*(1-C$5))+(Inputs!$C$26*(((Inputs!$D$7*(1+$B$9))*Inputs!$D$8)+Inputs!$D$16))-MIN(MAX(Inputs!$C$11-Inputs!$C$25,0),(((Inputs!$D$7*(1+$B$9))*Inputs!$D$8)*(1-C$5))+(Inputs!$C$26*(((Inputs!$D$7*(1+$B$9))*Inputs!$D$8)+Inputs!$D$16))))/(1-Inputs!$C$27))*Inputs!$C$27/Inputs!$C$28)*(1-Inputs!$C$32))/(Inputs!$C$8+(((Inputs!$D$7*(1+$B$9))*Inputs!$D$8)*C$5/Inputs!$C$7))/(Inputs!$C$9*(1+Inputs!$C$33)^1)-1 -> 0.00039903175 | D9: =((Inputs!$C$9*(1+Inputs!$C$33)^1)*Inputs!$C$8+Inputs!$D$9*(1+Inputs!$C$34)^1*Inputs!$D$8+(Inputs!$C$31*Inputs!$D$35-(((((Inputs!$D$7*(1+$B$9))*Inputs!$D$8)*(1-D$5))+(Inputs!$C$26*(((Inputs!$D$7*(1+$B$9))*Inputs!$D$8)+Inputs!$D$16))-MIN(MAX(Inputs!$C$11-Inputs!$C$25,0),(((Inputs!$D$7*(1+$B$9))*Inputs!$D$8)*(1-D$5))+(Inputs!$C$26*(((Inputs!$D$7*(1+$B$9))*Inputs!$D$8)+Inputs!$D$16))))/(1-Inputs!$C$27))*Inputs!$C$23-MIN(MAX(Inputs!$C$11-Inputs!$C$25,0),(((Inputs!$D$7*(1+$B$9))*Inputs!$D$8)*(1-D$5))+(Inputs!$C$26*(((Inputs!$D$7*(1+$B$9))*Inputs!$D$8)+Inputs!$D$16)))*Inputs!$C$24-(Inputs!$C$29*(((Inputs!$D$7*(1+$B$9))*Inputs!$D$8)-Inputs!$D$14))/Inputs!$C$30-(((((Inputs!$D$7*(1+$B$9))*Inputs!$D$8)*(1-D$5))+(Inputs!$C$26*(((Inputs!$D$7*(1+$B$9))*Inputs!$D$8)+Inputs!$D$16))-MIN(MAX(Inputs!$C$11-Inputs!$C$25,0),(((Inputs!$D$7*(1+$B$9))*Inputs!$D$8)*(1-D$5))+(Inputs!$C$26*(((Inputs!$D$7*(1+$B$9))*Inputs!$D$8)+Inputs!$D$16))))/(1-Inputs!$C$27))*Inputs!$C$27/Inputs!$C$28)*(1-Inputs!$C$32))/(Inputs!$C$8+(((Inputs!$D$7*(1+$B$9))*Inputs!$D$8)*D$5/Inputs!$C$7))/(Inputs!$C$9*(1+Inputs!$C$33)^1)-1 -> -0.006489105 | E9: =((Inputs!$C$9*(1+Inputs!$C$33)^1)*Inputs!$C$8+Inputs!$D$9*(1+Inputs!$C$34)^1*Inputs!$D$8+(Inputs!$C$31*Inputs!$D$35-(((((Inputs!$D$7*(1+$B$9))*Inputs!$D$8)*(1-E$5))+(Inputs!$C$26*(((Inputs!$D$7*(1+$B$9))*Inputs!$D$8)+Inputs!$D$16))-MIN(MAX(Inputs!$C$11-Inputs!$C$25,0),(((Inputs!$D$7*(1+$B$9))*Inputs!$D$8)*(1-E$5))+(Inputs!$C$26*(((Inputs!$D$7*(1+$B$9))*Inputs!$D$8)+Inputs!$D$16))))/(1-Inputs!$C$27))*Inputs!$C$23-MIN(MAX(Inputs!$C$11-Inputs!$C$25,0),(((Inputs!$D$7*(1+$B$9))*Inputs!$D$8)*(1-E$5))+(Inputs!$C$26*(((Inputs!$D$7*(1+$B$9))*Inputs!$D$8)+Inputs!$D$16)))*Inputs!$C$24-(Inputs!$C$29*(((Inputs!$D$7*(1+$B$9))*Inputs!$D$8)-Inputs!$D$14))/Inputs!$C$30-(((((Inputs!$D$7*(1+$B$9))*Inputs!$D$8)*(1-E$5))+(Inputs!$C$26*(((Inputs!$D$7*(1+$B$9))*Inputs!$D$8)+Inputs!$D$16))-MIN(MAX(Inputs!$C$11-Inputs!$C$25,0),(((Inputs!$D$7*(1+$B$9))*Inputs!$D$8)*(1-E$5))+(Inputs!$C$26*(((Inputs!$D$7*(1+$B$9))*Inputs!$D$8)+Inputs!$D$16))))/(1-Inputs!$C$27))*Inputs!$C$27/Inputs!$C$28)*(1-Inputs!$C$32))/(Inputs!$C$8+(((Inputs!$D$7*(1+$B$9))*Inputs!$D$8)*E$5/Inputs!$C$7))/(Inputs!$C$9*(1+Inputs!$C$33)^1)-1 -> -0.012676599 | F9: =((Inputs!$C$9*(1+Inputs!$C$33)^1)*Inputs!$C$8+Inputs!$D$9*(1+Inputs!$C$34)^1*Inputs!$D$8+(Inputs!$C$31*Inputs!$D$35-(((((Inputs!$D$7*(1+$B$9))*Inputs!$D$8)*(1-F$5))+(Inputs!$C$26*(((Inputs!$D$7*(1+$B$9))*Inputs!$D$8)+Inputs!$D$16))-MIN(MAX(Inputs!$C$11-Inputs!$C$25,0),(((Inputs!$D$7*(1+$B$9))*Inputs!$D$8)*(1-F$5))+(Inputs!$C$26*(((Inputs!$D$7*(1+$B$9))*Inputs!$D$8)+Inputs!$D$16))))/(1-Inputs!$C$27))*Inputs!$C$23-MIN(MAX(Inputs!$C$11-Inputs!$C$25,0),(((Inputs!$D$7*(1+$B$9))*Inputs!$D$8)*(1-F$5))+(Inputs!$C$26*(((Inputs!$D$7*(1+$B$9))*Inputs!$D$8)+Inputs!$D$16)))*Inputs!$C$24-(Inputs!$C$29*(((Inputs!$D$7*(1+$B$9))*Inputs!$D$8)-Inputs!$D$14))/Inputs!$C$30-(((((Inputs!$D$7*(1+$B$9))*Inputs!$D$8)*(1-F$5))+(Inputs!$C$26*(((Inputs!$D$7*(1+$B$9))*Inputs!$D$8)+Inputs!$D$16))-MIN(MAX(Inputs!$C$11-Inputs!$C$25,0),(((Inputs!$D$7*(1+$B$9))*Inputs!$D$8)*(1-F$5))+(Inputs!$C$26*(((Inputs!$D$7*(1+$B$9))*Inputs!$D$8)+Inputs!$D$16))))/(1-Inputs!$C$27))*Inputs!$C$27/Inputs!$C$28)*(1-Inputs!$C$32))/(Inputs!$C$8+(((Inputs!$D$7*(1+$B$9))*Inputs!$D$8)*F$5/Inputs!$C$7))/(Inputs!$C$9*(1+Inputs!$C$33)^1)-1 -> -0.018265178 | G9: =((Inputs!$C$9*(1+Inputs!$C$33)^1)*Inputs!$C$8+Inputs!$D$9*(1+Inputs!$C$34)^1*Inputs!$D$8+(Inputs!$C$31*Inputs!$D$35-(((((Inputs!$D$7*(1+$B$9))*Inputs!$D$8)*(1-G$5))+(Inputs!$C$26*(((Inputs!$D$7*(1+$B$9))*Inputs!$D$8)+Inputs!$D$16))-MIN(MAX(Inputs!$C$11-Inputs!$C$25,0),(((Inputs!$D$7*(1+$B$9))*Inputs!$D$8)*(1-G$5))+(Inputs!$C$26*(((Inputs!$D$7*(1+$B$9))*Inputs!$D$8)+Inputs!$D$16))))/(1-Inputs!$C$27))*Inputs!$C$23-MIN(MAX(Inputs!$C$11-Inputs!$C$25,0),(((Inputs!$D$7*(1+$B$9))*Inputs!$D$8)*(1-G$5))+(Inputs!$C$26*(((Inputs!$D$7*(1+$B$9))*Inputs!$D$8)+Inputs!$D$16)))*Inputs!$C$24-(Inputs!$C$29*(((Inputs!$D$7*(1+$B$9))*Inputs!$D$8)-Inputs!$D$14))/Inputs!$C$30-(((((Inputs!$D$7*(1+$B$9))*Inputs!$D$8)*(1-G$5))+(Inputs!$C$26*(((Inputs!$D$7*(1+$B$9))*Inputs!$D$8)+Inputs!$D$16))-MIN(MAX(Inputs!$C$11-Inputs!$C$25,0),(((Inputs!$D$7*(1+$B$9))*Inputs!$D$8)*(1-G$5))+(Inputs!$C$26*(((Inputs!$D$7*(1+$B$9))*Inputs!$D$8)+Inputs!$D$16))))/(1-Inputs!$C$27))*Inputs!$C$27/Inputs!$C$28)*(1-Inputs!$C$32))/(Inputs!$C$8+(((Inputs!$D$7*(1+$B$9))*Inputs!$D$8)*G$5/Inputs!$C$7))/(Inputs!$C$9*(1+Inputs!$C$33)^1)-1 -> -0.027724429
B10: 0.45 | C10: =((Inputs!$C$9*(1+Inputs!$C$33)^1)*Inputs!$C$8+Inputs!$D$9*(1+Inputs!$C$34)^1*Inputs!$D$8+(Inputs!$C$31*Inputs!$D$35-(((((Inputs!$D$7*(1+$B$10))*Inputs!$D$8)*(1-C$5))+(Inputs!$C$26*(((Inputs!$D$7*(1+$B$10))*Inputs!$D$8)+Inputs!$D$16))-MIN(MAX(Inputs!$C$11-Inputs!$C$25,0),(((Inputs!$D$7*(1+$B$10))*Inputs!$D$8)*(1-C$5))+(Inputs!$C$26*(((Inputs!$D$7*(1+$B$10))*Inputs!$D$8)+Inputs!$D$16))))/(1-Inputs!$C$27))*Inputs!$C$23-MIN(MAX(Inputs!$C$11-Inputs!$C$25,0),(((Inputs!$D$7*(1+$B$10))*Inputs!$D$8)*(1-C$5))+(Inputs!$C$26*(((Inputs!$D$7*(1+$B$10))*Inputs!$D$8)+Inputs!$D$16)))*Inputs!$C$24-(Inputs!$C$29*(((Inputs!$D$7*(1+$B$10))*Inputs!$D$8)-Inputs!$D$14))/Inputs!$C$30-(((((Inputs!$D$7*(1+$B$10))*Inputs!$D$8)*(1-C$5))+(Inputs!$C$26*(((Inputs!$D$7*(1+$B$10))*Inputs!$D$8)+Inputs!$D$16))-MIN(MAX(Inputs!$C$11-Inputs!$C$25,0),(((Inputs!$D$7*(1+$B$10))*Inputs!$D$8)*(1-C$5))+(Inputs!$C$26*(((Inputs!$D$7*(1+$B$10))*Inputs!$D$8)+Inputs!$D$16))))/(1-Inputs!$C$27))*Inputs!$C$27/Inputs!$C$28)*(1-Inputs!$C$32))/(Inputs!$C$8+(((Inputs!$D$7*(1+$B$10))*Inputs!$D$8)*C$5/Inputs!$C$7))/(Inputs!$C$9*(1+Inputs!$C$33)^1)-1 -> -0.013298669 | D10: =((Inputs!$C$9*(1+Inputs!$C$33)^1)*Inputs!$C$8+Inputs!$D$9*(1+Inputs!$C$34)^1*Inputs!$D$8+(Inputs!$C$31*Inputs!$D$35-(((((Inputs!$D$7*(1+$B$10))*Inputs!$D$8)*(1-D$5))+(Inputs!$C$26*(((Inputs!$D$7*(1+$B$10))*Inputs!$D$8)+Inputs!$D$16))-MIN(MAX(Inputs!$C$11-Inputs!$C$25,0),(((Inputs!$D$7*(1+$B$10))*Inputs!$D$8)*(1-D$5))+(Inputs!$C$26*(((Inputs!$D$7*(1+$B$10))*Inputs!$D$8)+Inputs!$D$16))))/(1-Inputs!$C$27))*Inputs!$C$23-MIN(MAX(Inputs!$C$11-Inputs!$C$25,0),(((Inputs!$D$7*(1+$B$10))*Inputs!$D$8)*(1-D$5))+(Inputs!$C$26*(((Inputs!$D$7*(1+$B$10))*Inputs!$D$8)+Inputs!$D$16)))*Inputs!$C$24-(Inputs!$C$29*(((Inputs!$D$7*(1+$B$10))*Inputs!$D$8)-Inputs!$D$14))/Inputs!$C$30-(((((Inputs!$D$7*(1+$B$10))*Inputs!$D$8)*(1-D$5))+(Inputs!$C$26*(((Inputs!$D$7*(1+$B$10))*Inputs!$D$8)+Inputs!$D$16))-MIN(MAX(Inputs!$C$11-Inputs!$C$25,0),(((Inputs!$D$7*(1+$B$10))*Inputs!$D$8)*(1-D$5))+(Inputs!$C$26*(((Inputs!$D$7*(1+$B$10))*Inputs!$D$8)+Inputs!$D$16))))/(1-Inputs!$C$27))*Inputs!$C$27/Inputs!$C$28)*(1-Inputs!$C$32))/(Inputs!$C$8+(((Inputs!$D$7*(1+$B$10))*Inputs!$D$8)*D$5/Inputs!$C$7))/(Inputs!$C$9*(1+Inputs!$C$33)^1)-1 -> -0.019769599 | E10: =((Inputs!$C$9*(1+Inputs!$C$33)^1)*Inputs!$C$8+Inputs!$D$9*(1+Inputs!$C$34)^1*Inputs!$D$8+(Inputs!$C$31*Inputs!$D$35-(((((Inputs!$D$7*(1+$B$10))*Inputs!$D$8)*(1-E$5))+(Inputs!$C$26*(((Inputs!$D$7*(1+$B$10))*Inputs!$D$8)+Inputs!$D$16))-MIN(MAX(Inputs!$C$11-Inputs!$C$25,0),(((Inputs!$D$7*(1+$B$10))*Inputs!$D$8)*(1-E$5))+(Inputs!$C$26*(((Inputs!$D$7*(1+$B$10))*Inputs!$D$8)+Inputs!$D$16))))/(1-Inputs!$C$27))*Inputs!$C$23-MIN(MAX(Inputs!$C$11-Inputs!$C$25,0),(((Inputs!$D$7*(1+$B$10))*Inputs!$D$8)*(1-E$5))+(Inputs!$C$26*(((Inputs!$D$7*(1+$B$10))*Inputs!$D$8)+Inputs!$D$16)))*Inputs!$C$24-(Inputs!$C$29*(((Inputs!$D$7*(1+$B$10))*Inputs!$D$8)-Inputs!$D$14))/Inputs!$C$30-(((((Inputs!$D$7*(1+$B$10))*Inputs!$D$8)*(1-E$5))+(Inputs!$C$26*(((Inputs!$D$7*(1+$B$10))*Inputs!$D$8)+Inputs!$D$16))-MIN(MAX(Inputs!$C$11-Inputs!$C$25,0),(((Inputs!$D$7*(1+$B$10))*Inputs!$D$8)*(1-E$5))+(Inputs!$C$26*(((Inputs!$D$7*(1+$B$10))*Inputs!$D$8)+Inputs!$D$16))))/(1-Inputs!$C$27))*Inputs!$C$27/Inputs!$C$28)*(1-Inputs!$C$32))/(Inputs!$C$8+(((Inputs!$D$7*(1+$B$10))*Inputs!$D$8)*E$5/Inputs!$C$7))/(Inputs!$C$9*(1+Inputs!$C$33)^1)-1 -> -0.02555025 | F10: =((Inputs!$C$9*(1+Inputs!$C$33)^1)*Inputs!$C$8+Inputs!$D$9*(1+Inputs!$C$34)^1*Inputs!$D$8+(Inputs!$C$31*Inputs!$D$35-(((((Inputs!$D$7*(1+$B$10))*Inputs!$D$8)*(1-F$5))+(Inputs!$C$26*(((Inputs!$D$7*(1+$B$10))*Inputs!$D$8)+Inputs!$D$16))-MIN(MAX(Inputs!$C$11-Inputs!$C$25,0),(((Inputs!$D$7*(1+$B$10))*Inputs!$D$8)*(1-F$5))+(Inputs!$C$26*(((Inputs!$D$7*(1+$B$10))*Inputs!$D$8)+Inputs!$D$16))))/(1-Inputs!$C$27))*Inputs!$C$23-MIN(MAX(Inputs!$C$11-Inputs!$C$25,0),(((Inputs!$D$7*(1+$B$10))*Inputs!$D$8)*(1-F$5))+(Inputs!$C$26*(((Inputs!$D$7*(1+$B$10))*Inputs!$D$8)+Inputs!$D$16)))*Inputs!$C$24-(Inputs!$C$29*(((Inputs!$D$7*(1+$B$10))*Inputs!$D$8)-Inputs!$D$14))/Inputs!$C$30-(((((Inputs!$D$7*(1+$B$10))*Inputs!$D$8)*(1-F$5))+(Inputs!$C$26*(((Inputs!$D$7*(1+$B$10))*Inputs!$D$8)+Inputs!$D$16))-MIN(MAX(Inputs!$C$11-Inputs!$C$25,0),(((Inputs!$D$7*(1+$B$10))*Inputs!$D$8)*(1-F$5))+(Inputs!$C$26*(((Inputs!$D$7*(1+$B$10))*Inputs!$D$8)+Inputs!$D$16))))/(1-Inputs!$C$27))*Inputs!$C$27/Inputs!$C$28)*(1-Inputs!$C$32))/(Inputs!$C$8+(((Inputs!$D$7*(1+$B$10))*Inputs!$D$8)*F$5/Inputs!$C$7))/(Inputs!$C$9*(1+Inputs!$C$33)^1)-1 -> -0.030745483 | G10: =((Inputs!$C$9*(1+Inputs!$C$33)^1)*Inputs!$C$8+Inputs!$D$9*(1+Inputs!$C$34)^1*Inputs!$D$8+(Inputs!$C$31*Inputs!$D$35-(((((Inputs!$D$7*(1+$B$10))*Inputs!$D$8)*(1-G$5))+(Inputs!$C$26*(((Inputs!$D$7*(1+$B$10))*Inputs!$D$8)+Inputs!$D$16))-MIN(MAX(Inputs!$C$11-Inputs!$C$25,0),(((Inputs!$D$7*(1+$B$10))*Inputs!$D$8)*(1-G$5))+(Inputs!$C$26*(((Inputs!$D$7*(1+$B$10))*Inputs!$D$8)+Inputs!$D$16))))/(1-Inputs!$C$27))*Inputs!$C$23-MIN(MAX(Inputs!$C$11-Inputs!$C$25,0),(((Inputs!$D$7*(1+$B$10))*Inputs!$D$8)*(1-G$5))+(Inputs!$C$26*(((Inputs!$D$7*(1+$B$10))*Inputs!$D$8)+Inputs!$D$16)))*Inputs!$C$24-(Inputs!$C$29*(((Inputs!$D$7*(1+$B$10))*Inputs!$D$8)-Inputs!$D$14))/Inputs!$C$30-(((((Inputs!$D$7*(1+$B$10))*Inputs!$D$8)*(1-G$5))+(Inputs!$C$26*(((Inputs!$D$7*(1+$B$10))*Inputs!$D$8)+Inputs!$D$16))-MIN(MAX(Inputs!$C$11-Inputs!$C$25,0),(((Inputs!$D$7*(1+$B$10))*Inputs!$D$8)*(1-G$5))+(Inputs!$C$26*(((Inputs!$D$7*(1+$B$10))*Inputs!$D$8)+Inputs!$D$16))))/(1-Inputs!$C$27))*Inputs!$C$27/Inputs!$C$28)*(1-Inputs!$C$32))/(Inputs!$C$8+(((Inputs!$D$7*(1+$B$10))*Inputs!$D$8)*G$5/Inputs!$C$7))/(Inputs!$C$9*(1+Inputs!$C$33)^1)-1 -> -0.03974358
B12: Run-rate synergies, $mm (rows) × % stock (columns)
B13: ↓ rows / % stock → | C13: 0 | D13: 0.25 | E13: 0.5 | F13: 0.75 | G13: 1
B14: 0 | C14: =((Inputs!$C$9*(1+Inputs!$C$33)^1)*Inputs!$C$8+Inputs!$D$9*(1+Inputs!$C$34)^1*Inputs!$D$8+($B$14*Inputs!$D$35-(((((Inputs!$D$7*(1+Inputs!$C$21))*Inputs!$D$8)*(1-C$13))+(Inputs!$C$26*(((Inputs!$D$7*(1+Inputs!$C$21))*Inputs!$D$8)+Inputs!$D$16))-MIN(MAX(Inputs!$C$11-Inputs!$C$25,0),(((Inputs!$D$7*(1+Inputs!$C$21))*Inputs!$D$8)*(1-C$13))+(Inputs!$C$26*(((Inputs!$D$7*(1+Inputs!$C$21))*Inputs!$D$8)+Inputs!$D$16))))/(1-Inputs!$C$27))*Inputs!$C$23-MIN(MAX(Inputs!$C$11-Inputs!$C$25,0),(((Inputs!$D$7*(1+Inputs!$C$21))*Inputs!$D$8)*(1-C$13))+(Inputs!$C$26*(((Inputs!$D$7*(1+Inputs!$C$21))*Inputs!$D$8)+Inputs!$D$16)))*Inputs!$C$24-(Inputs!$C$29*(((Inputs!$D$7*(1+Inputs!$C$21))*Inputs!$D$8)-Inputs!$D$14))/Inputs!$C$30-(((((Inputs!$D$7*(1+Inputs!$C$21))*Inputs!$D$8)*(1-C$13))+(Inputs!$C$26*(((Inputs!$D$7*(1+Inputs!$C$21))*Inputs!$D$8)+Inputs!$D$16))-MIN(MAX(Inputs!$C$11-Inputs!$C$25,0),(((Inputs!$D$7*(1+Inputs!$C$21))*Inputs!$D$8)*(1-C$13))+(Inputs!$C$26*(((Inputs!$D$7*(1+Inputs!$C$21))*Inputs!$D$8)+Inputs!$D$16))))/(1-Inputs!$C$27))*Inputs!$C$27/Inputs!$C$28)*(1-Inputs!$C$32))/(Inputs!$C$8+(((Inputs!$D$7*(1+Inputs!$C$21))*Inputs!$D$8)*C$13/Inputs!$C$7))/(Inputs!$C$9*(1+Inputs!$C$33)^1)-1 -> -0.03920891 | D14: =((Inputs!$C$9*(1+Inputs!$C$33)^1)*Inputs!$C$8+Inputs!$D$9*(1+Inputs!$C$34)^1*Inputs!$D$8+($B$14*Inputs!$D$35-(((((Inputs!$D$7*(1+Inputs!$C$21))*Inputs!$D$8)*(1-D$13))+(Inputs!$C$26*(((Inputs!$D$7*(1+Inputs!$C$21))*Inputs!$D$8)+Inputs!$D$16))-MIN(MAX(Inputs!$C$11-Inputs!$C$25,0),(((Inputs!$D$7*(1+Inputs!$C$21))*Inputs!$D$8)*(1-D$13))+(Inputs!$C$26*(((Inputs!$D$7*(1+Inputs!$C$21))*Inputs!$D$8)+Inputs!$D$16))))/(1-Inputs!$C$27))*Inputs!$C$23-MIN(MAX(Inputs!$C$11-Inputs!$C$25,0),(((Inputs!$D$7*(1+Inputs!$C$21))*Inputs!$D$8)*(1-D$13))+(Inputs!$C$26*(((Inputs!$D$7*(1+Inputs!$C$21))*Inputs!$D$8)+Inputs!$D$16)))*Inputs!$C$24-(Inputs!$C$29*(((Inputs!$D$7*(1+Inputs!$C$21))*Inputs!$D$8)-Inputs!$D$14))/Inputs!$C$30-(((((Inputs!$D$7*(1+Inputs!$C$21))*Inputs!$D$8)*(1-D$13))+(Inputs!$C$26*(((Inputs!$D$7*(1+Inputs!$C$21))*Inputs!$D$8)+Inputs!$D$16))-MIN(MAX(Inputs!$C$11-Inputs!$C$25,0),(((Inputs!$D$7*(1+Inputs!$C$21))*Inputs!$D$8)*(1-D$13))+(Inputs!$C$26*(((Inputs!$D$7*(1+Inputs!$C$21))*Inputs!$D$8)+Inputs!$D$16))))/(1-Inputs!$C$27))*Inputs!$C$27/Inputs!$C$28)*(1-Inputs!$C$32))/(Inputs!$C$8+(((Inputs!$D$7*(1+Inputs!$C$21))*Inputs!$D$8)*D$13/Inputs!$C$7))/(Inputs!$C$9*(1+Inputs!$C$33)^1)-1 -> -0.043727956 | E14: =((Inputs!$C$9*(1+Inputs!$C$33)^1)*Inputs!$C$8+Inputs!$D$9*(1+Inputs!$C$34)^1*Inputs!$D$8+($B$14*Inputs!$D$35-(((((Inputs!$D$7*(1+Inputs!$C$21))*Inputs!$D$8)*(1-E$13))+(Inputs!$C$26*(((Inputs!$D$7*(1+Inputs!$C$21))*Inputs!$D$8)+Inputs!$D$16))-MIN(MAX(Inputs!$C$11-Inputs!$C$25,0),(((Inputs!$D$7*(1+Inputs!$C$21))*Inputs!$D$8)*(1-E$13))+(Inputs!$C$26*(((Inputs!$D$7*(1+Inputs!$C$21))*Inputs!$D$8)+Inputs!$D$16))))/(1-Inputs!$C$27))*Inputs!$C$23-MIN(MAX(Inputs!$C$11-Inputs!$C$25,0),(((Inputs!$D$7*(1+Inputs!$C$21))*Inputs!$D$8)*(1-E$13))+(Inputs!$C$26*(((Inputs!$D$7*(1+Inputs!$C$21))*Inputs!$D$8)+Inputs!$D$16)))*Inputs!$C$24-(Inputs!$C$29*(((Inputs!$D$7*(1+Inputs!$C$21))*Inputs!$D$8)-Inputs!$D$14))/Inputs!$C$30-(((((Inputs!$D$7*(1+Inputs!$C$21))*Inputs!$D$8)*(1-E$13))+(Inputs!$C$26*(((Inputs!$D$7*(1+Inputs!$C$21))*Inputs!$D$8)+Inputs!$D$16))-MIN(MAX(Inputs!$C$11-Inputs!$C$25,0),(((Inputs!$D$7*(1+Inputs!$C$21))*Inputs!$D$8)*(1-E$13))+(Inputs!$C$26*(((Inputs!$D$7*(1+Inputs!$C$21))*Inputs!$D$8)+Inputs!$D$16))))/(1-Inputs!$C$27))*Inputs!$C$27/Inputs!$C$28)*(1-Inputs!$C$32))/(Inputs!$C$8+(((Inputs!$D$7*(1+Inputs!$C$21))*Inputs!$D$8)*E$13/Inputs!$C$7))/(Inputs!$C$9*(1+Inputs!$C$33)^1)-1 -> -0.047809985 | F14: =((Inputs!$C$9*(1+Inputs!$C$33)^1)*Inputs!$C$8+Inputs!$D$9*(1+Inputs!$C$34)^1*Inputs!$D$8+($B$14*Inputs!$D$35-(((((Inputs!$D$7*(1+Inputs!$C$21))*Inputs!$D$8)*(1-F$13))+(Inputs!$C$26*(((Inputs!$D$7*(1+Inputs!$C$21))*Inputs!$D$8)+Inputs!$D$16))-MIN(MAX(Inputs!$C$11-Inputs!$C$25,0),(((Inputs!$D$7*(1+Inputs!$C$21))*Inputs!$D$8)*(1-F$13))+(Inputs!$C$26*(((Inputs!$D$7*(1+Inputs!$C$21))*Inputs!$D$8)+Inputs!$D$16))))/(1-Inputs!$C$27))*Inputs!$C$23-MIN(MAX(Inputs!$C$11-Inputs!$C$25,0),(((Inputs!$D$7*(1+Inputs!$C$21))*Inputs!$D$8)*(1-F$13))+(Inputs!$C$26*(((Inputs!$D$7*(1+Inputs!$C$21))*Inputs!$D$8)+Inputs!$D$16)))*Inputs!$C$24-(Inputs!$C$29*(((Inputs!$D$7*(1+Inputs!$C$21))*Inputs!$D$8)-Inputs!$D$14))/Inputs!$C$30-(((((Inputs!$D$7*(1+Inputs!$C$21))*Inputs!$D$8)*(1-F$13))+(Inputs!$C$26*(((Inputs!$D$7*(1+Inputs!$C$21))*Inputs!$D$8)+Inputs!$D$16))-MIN(MAX(Inputs!$C$11-Inputs!$C$25,0),(((Inputs!$D$7*(1+Inputs!$C$21))*Inputs!$D$8)*(1-F$13))+(Inputs!$C$26*(((Inputs!$D$7*(1+Inputs!$C$21))*Inputs!$D$8)+Inputs!$D$16))))/(1-Inputs!$C$27))*Inputs!$C$27/Inputs!$C$28)*(1-Inputs!$C$32))/(Inputs!$C$8+(((Inputs!$D$7*(1+Inputs!$C$21))*Inputs!$D$8)*F$13/Inputs!$C$7))/(Inputs!$C$9*(1+Inputs!$C$33)^1)-1 -> -0.051515466 | G14: =((Inputs!$C$9*(1+Inputs!$C$33)^1)*Inputs!$C$8+Inputs!$D$9*(1+Inputs!$C$34)^1*Inputs!$D$8+($B$14*Inputs!$D$35-(((((Inputs!$D$7*(1+Inputs!$C$21))*Inputs!$D$8)*(1-G$13))+(Inputs!$C$26*(((Inputs!$D$7*(1+Inputs!$C$21))*Inputs!$D$8)+Inputs!$D$16))-MIN(MAX(Inputs!$C$11-Inputs!$C$25,0),(((Inputs!$D$7*(1+Inputs!$C$21))*Inputs!$D$8)*(1-G$13))+(Inputs!$C$26*(((Inputs!$D$7*(1+Inputs!$C$21))*Inputs!$D$8)+Inputs!$D$16))))/(1-Inputs!$C$27))*Inputs!$C$23-MIN(MAX(Inputs!$C$11-Inputs!$C$25,0),(((Inputs!$D$7*(1+Inputs!$C$21))*Inputs!$D$8)*(1-G$13))+(Inputs!$C$26*(((Inputs!$D$7*(1+Inputs!$C$21))*Inputs!$D$8)+Inputs!$D$16)))*Inputs!$C$24-(Inputs!$C$29*(((Inputs!$D$7*(1+Inputs!$C$21))*Inputs!$D$8)-Inputs!$D$14))/Inputs!$C$30-(((((Inputs!$D$7*(1+Inputs!$C$21))*Inputs!$D$8)*(1-G$13))+(Inputs!$C$26*(((Inputs!$D$7*(1+Inputs!$C$21))*Inputs!$D$8)+Inputs!$D$16))-MIN(MAX(Inputs!$C$11-Inputs!$C$25,0),(((Inputs!$D$7*(1+Inputs!$C$21))*Inputs!$D$8)*(1-G$13))+(Inputs!$C$26*(((Inputs!$D$7*(1+Inputs!$C$21))*Inputs!$D$8)+Inputs!$D$16))))/(1-Inputs!$C$27))*Inputs!$C$27/Inputs!$C$28)*(1-Inputs!$C$32))/(Inputs!$C$8+(((Inputs!$D$7*(1+Inputs!$C$21))*Inputs!$D$8)*G$13/Inputs!$C$7))/(Inputs!$C$9*(1+Inputs!$C$33)^1)-1 -> -0.059365543
B15: 250 | C15: =((Inputs!$C$9*(1+Inputs!$C$33)^1)*Inputs!$C$8+Inputs!$D$9*(1+Inputs!$C$34)^1*Inputs!$D$8+($B$15*Inputs!$D$35-(((((Inputs!$D$7*(1+Inputs!$C$21))*Inputs!$D$8)*(1-C$13))+(Inputs!$C$26*(((Inputs!$D$7*(1+Inputs!$C$21))*Inputs!$D$8)+Inputs!$D$16))-MIN(MAX(Inputs!$C$11-Inputs!$C$25,0),(((Inputs!$D$7*(1+Inputs!$C$21))*Inputs!$D$8)*(1-C$13))+(Inputs!$C$26*(((Inputs!$D$7*(1+Inputs!$C$21))*Inputs!$D$8)+Inputs!$D$16))))/(1-Inputs!$C$27))*Inputs!$C$23-MIN(MAX(Inputs!$C$11-Inputs!$C$25,0),(((Inputs!$D$7*(1+Inputs!$C$21))*Inputs!$D$8)*(1-C$13))+(Inputs!$C$26*(((Inputs!$D$7*(1+Inputs!$C$21))*Inputs!$D$8)+Inputs!$D$16)))*Inputs!$C$24-(Inputs!$C$29*(((Inputs!$D$7*(1+Inputs!$C$21))*Inputs!$D$8)-Inputs!$D$14))/Inputs!$C$30-(((((Inputs!$D$7*(1+Inputs!$C$21))*Inputs!$D$8)*(1-C$13))+(Inputs!$C$26*(((Inputs!$D$7*(1+Inputs!$C$21))*Inputs!$D$8)+Inputs!$D$16))-MIN(MAX(Inputs!$C$11-Inputs!$C$25,0),(((Inputs!$D$7*(1+Inputs!$C$21))*Inputs!$D$8)*(1-C$13))+(Inputs!$C$26*(((Inputs!$D$7*(1+Inputs!$C$21))*Inputs!$D$8)+Inputs!$D$16))))/(1-Inputs!$C$27))*Inputs!$C$27/Inputs!$C$28)*(1-Inputs!$C$32))/(Inputs!$C$8+(((Inputs!$D$7*(1+Inputs!$C$21))*Inputs!$D$8)*C$13/Inputs!$C$7))/(Inputs!$C$9*(1+Inputs!$C$33)^1)-1 -> -0.012556089 | D15: =((Inputs!$C$9*(1+Inputs!$C$33)^1)*Inputs!$C$8+Inputs!$D$9*(1+Inputs!$C$34)^1*Inputs!$D$8+($B$15*Inputs!$D$35-(((((Inputs!$D$7*(1+Inputs!$C$21))*Inputs!$D$8)*(1-D$13))+(Inputs!$C$26*(((Inputs!$D$7*(1+Inputs!$C$21))*Inputs!$D$8)+Inputs!$D$16))-MIN(MAX(Inputs!$C$11-Inputs!$C$25,0),(((Inputs!$D$7*(1+Inputs!$C$21))*Inputs!$D$8)*(1-D$13))+(Inputs!$C$26*(((Inputs!$D$7*(1+Inputs!$C$21))*Inputs!$D$8)+Inputs!$D$16))))/(1-Inputs!$C$27))*Inputs!$C$23-MIN(MAX(Inputs!$C$11-Inputs!$C$25,0),(((Inputs!$D$7*(1+Inputs!$C$21))*Inputs!$D$8)*(1-D$13))+(Inputs!$C$26*(((Inputs!$D$7*(1+Inputs!$C$21))*Inputs!$D$8)+Inputs!$D$16)))*Inputs!$C$24-(Inputs!$C$29*(((Inputs!$D$7*(1+Inputs!$C$21))*Inputs!$D$8)-Inputs!$D$14))/Inputs!$C$30-(((((Inputs!$D$7*(1+Inputs!$C$21))*Inputs!$D$8)*(1-D$13))+(Inputs!$C$26*(((Inputs!$D$7*(1+Inputs!$C$21))*Inputs!$D$8)+Inputs!$D$16))-MIN(MAX(Inputs!$C$11-Inputs!$C$25,0),(((Inputs!$D$7*(1+Inputs!$C$21))*Inputs!$D$8)*(1-D$13))+(Inputs!$C$26*(((Inputs!$D$7*(1+Inputs!$C$21))*Inputs!$D$8)+Inputs!$D$16))))/(1-Inputs!$C$27))*Inputs!$C$27/Inputs!$C$28)*(1-Inputs!$C$32))/(Inputs!$C$8+(((Inputs!$D$7*(1+Inputs!$C$21))*Inputs!$D$8)*D$13/Inputs!$C$7))/(Inputs!$C$9*(1+Inputs!$C$33)^1)-1 -> -0.018429354 | E15: =((Inputs!$C$9*(1+Inputs!$C$33)^1)*Inputs!$C$8+Inputs!$D$9*(1+Inputs!$C$34)^1*Inputs!$D$8+($B$15*Inputs!$D$35-(((((Inputs!$D$7*(1+Inputs!$C$21))*Inputs!$D$8)*(1-E$13))+(Inputs!$C$26*(((Inputs!$D$7*(1+Inputs!$C$21))*Inputs!$D$8)+Inputs!$D$16))-MIN(MAX(Inputs!$C$11-Inputs!$C$25,0),(((Inputs!$D$7*(1+Inputs!$C$21))*Inputs!$D$8)*(1-E$13))+(Inputs!$C$26*(((Inputs!$D$7*(1+Inputs!$C$21))*Inputs!$D$8)+Inputs!$D$16))))/(1-Inputs!$C$27))*Inputs!$C$23-MIN(MAX(Inputs!$C$11-Inputs!$C$25,0),(((Inputs!$D$7*(1+Inputs!$C$21))*Inputs!$D$8)*(1-E$13))+(Inputs!$C$26*(((Inputs!$D$7*(1+Inputs!$C$21))*Inputs!$D$8)+Inputs!$D$16)))*Inputs!$C$24-(Inputs!$C$29*(((Inputs!$D$7*(1+Inputs!$C$21))*Inputs!$D$8)-Inputs!$D$14))/Inputs!$C$30-(((((Inputs!$D$7*(1+Inputs!$C$21))*Inputs!$D$8)*(1-E$13))+(Inputs!$C$26*(((Inputs!$D$7*(1+Inputs!$C$21))*Inputs!$D$8)+Inputs!$D$16))-MIN(MAX(Inputs!$C$11-Inputs!$C$25,0),(((Inputs!$D$7*(1+Inputs!$C$21))*Inputs!$D$8)*(1-E$13))+(Inputs!$C$26*(((Inputs!$D$7*(1+Inputs!$C$21))*Inputs!$D$8)+Inputs!$D$16))))/(1-Inputs!$C$27))*Inputs!$C$27/Inputs!$C$28)*(1-Inputs!$C$32))/(Inputs!$C$8+(((Inputs!$D$7*(1+Inputs!$C$21))*Inputs!$D$8)*E$13/Inputs!$C$7))/(Inputs!$C$9*(1+Inputs!$C$33)^1)-1 -> -0.023734642 | F15: =((Inputs!$C$9*(1+Inputs!$C$33)^1)*Inputs!$C$8+Inputs!$D$9*(1+Inputs!$C$34)^1*Inputs!$D$8+($B$15*Inputs!$D$35-(((((Inputs!$D$7*(1+Inputs!$C$21))*Inputs!$D$8)*(1-F$13))+(Inputs!$C$26*(((Inputs!$D$7*(1+Inputs!$C$21))*Inputs!$D$8)+Inputs!$D$16))-MIN(MAX(Inputs!$C$11-Inputs!$C$25,0),(((Inputs!$D$7*(1+Inputs!$C$21))*Inputs!$D$8)*(1-F$13))+(Inputs!$C$26*(((Inputs!$D$7*(1+Inputs!$C$21))*Inputs!$D$8)+Inputs!$D$16))))/(1-Inputs!$C$27))*Inputs!$C$23-MIN(MAX(Inputs!$C$11-Inputs!$C$25,0),(((Inputs!$D$7*(1+Inputs!$C$21))*Inputs!$D$8)*(1-F$13))+(Inputs!$C$26*(((Inputs!$D$7*(1+Inputs!$C$21))*Inputs!$D$8)+Inputs!$D$16)))*Inputs!$C$24-(Inputs!$C$29*(((Inputs!$D$7*(1+Inputs!$C$21))*Inputs!$D$8)-Inputs!$D$14))/Inputs!$C$30-(((((Inputs!$D$7*(1+Inputs!$C$21))*Inputs!$D$8)*(1-F$13))+(Inputs!$C$26*(((Inputs!$D$7*(1+Inputs!$C$21))*Inputs!$D$8)+Inputs!$D$16))-MIN(MAX(Inputs!$C$11-Inputs!$C$25,0),(((Inputs!$D$7*(1+Inputs!$C$21))*Inputs!$D$8)*(1-F$13))+(Inputs!$C$26*(((Inputs!$D$7*(1+Inputs!$C$21))*Inputs!$D$8)+Inputs!$D$16))))/(1-Inputs!$C$27))*Inputs!$C$27/Inputs!$C$28)*(1-Inputs!$C$32))/(Inputs!$C$8+(((Inputs!$D$7*(1+Inputs!$C$21))*Inputs!$D$8)*F$13/Inputs!$C$7))/(Inputs!$C$9*(1+Inputs!$C$33)^1)-1 -> -0.028550542 | G15: =((Inputs!$C$9*(1+Inputs!$C$33)^1)*Inputs!$C$8+Inputs!$D$9*(1+Inputs!$C$34)^1*Inputs!$D$8+($B$15*Inputs!$D$35-(((((Inputs!$D$7*(1+Inputs!$C$21))*Inputs!$D$8)*(1-G$13))+(Inputs!$C$26*(((Inputs!$D$7*(1+Inputs!$C$21))*Inputs!$D$8)+Inputs!$D$16))-MIN(MAX(Inputs!$C$11-Inputs!$C$25,0),(((Inputs!$D$7*(1+Inputs!$C$21))*Inputs!$D$8)*(1-G$13))+(Inputs!$C$26*(((Inputs!$D$7*(1+Inputs!$C$21))*Inputs!$D$8)+Inputs!$D$16))))/(1-Inputs!$C$27))*Inputs!$C$23-MIN(MAX(Inputs!$C$11-Inputs!$C$25,0),(((Inputs!$D$7*(1+Inputs!$C$21))*Inputs!$D$8)*(1-G$13))+(Inputs!$C$26*(((Inputs!$D$7*(1+Inputs!$C$21))*Inputs!$D$8)+Inputs!$D$16)))*Inputs!$C$24-(Inputs!$C$29*(((Inputs!$D$7*(1+Inputs!$C$21))*Inputs!$D$8)-Inputs!$D$14))/Inputs!$C$30-(((((Inputs!$D$7*(1+Inputs!$C$21))*Inputs!$D$8)*(1-G$13))+(Inputs!$C$26*(((Inputs!$D$7*(1+Inputs!$C$21))*Inputs!$D$8)+Inputs!$D$16))-MIN(MAX(Inputs!$C$11-Inputs!$C$25,0),(((Inputs!$D$7*(1+Inputs!$C$21))*Inputs!$D$8)*(1-G$13))+(Inputs!$C$26*(((Inputs!$D$7*(1+Inputs!$C$21))*Inputs!$D$8)+Inputs!$D$16))))/(1-Inputs!$C$27))*Inputs!$C$27/Inputs!$C$28)*(1-Inputs!$C$32))/(Inputs!$C$8+(((Inputs!$D$7*(1+Inputs!$C$21))*Inputs!$D$8)*G$13/Inputs!$C$7))/(Inputs!$C$9*(1+Inputs!$C$33)^1)-1 -> -0.037413123
B16: 500 | C16: =((Inputs!$C$9*(1+Inputs!$C$33)^1)*Inputs!$C$8+Inputs!$D$9*(1+Inputs!$C$34)^1*Inputs!$D$8+($B$16*Inputs!$D$35-(((((Inputs!$D$7*(1+Inputs!$C$21))*Inputs!$D$8)*(1-C$13))+(Inputs!$C$26*(((Inputs!$D$7*(1+Inputs!$C$21))*Inputs!$D$8)+Inputs!$D$16))-MIN(MAX(Inputs!$C$11-Inputs!$C$25,0),(((Inputs!$D$7*(1+Inputs!$C$21))*Inputs!$D$8)*(1-C$13))+(Inputs!$C$26*(((Inputs!$D$7*(1+Inputs!$C$21))*Inputs!$D$8)+Inputs!$D$16))))/(1-Inputs!$C$27))*Inputs!$C$23-MIN(MAX(Inputs!$C$11-Inputs!$C$25,0),(((Inputs!$D$7*(1+Inputs!$C$21))*Inputs!$D$8)*(1-C$13))+(Inputs!$C$26*(((Inputs!$D$7*(1+Inputs!$C$21))*Inputs!$D$8)+Inputs!$D$16)))*Inputs!$C$24-(Inputs!$C$29*(((Inputs!$D$7*(1+Inputs!$C$21))*Inputs!$D$8)-Inputs!$D$14))/Inputs!$C$30-(((((Inputs!$D$7*(1+Inputs!$C$21))*Inputs!$D$8)*(1-C$13))+(Inputs!$C$26*(((Inputs!$D$7*(1+Inputs!$C$21))*Inputs!$D$8)+Inputs!$D$16))-MIN(MAX(Inputs!$C$11-Inputs!$C$25,0),(((Inputs!$D$7*(1+Inputs!$C$21))*Inputs!$D$8)*(1-C$13))+(Inputs!$C$26*(((Inputs!$D$7*(1+Inputs!$C$21))*Inputs!$D$8)+Inputs!$D$16))))/(1-Inputs!$C$27))*Inputs!$C$27/Inputs!$C$28)*(1-Inputs!$C$32))/(Inputs!$C$8+(((Inputs!$D$7*(1+Inputs!$C$21))*Inputs!$D$8)*C$13/Inputs!$C$7))/(Inputs!$C$9*(1+Inputs!$C$33)^1)-1 -> 0.014096732 | D16: =((Inputs!$C$9*(1+Inputs!$C$33)^1)*Inputs!$C$8+Inputs!$D$9*(1+Inputs!$C$34)^1*Inputs!$D$8+($B$16*Inputs!$D$35-(((((Inputs!$D$7*(1+Inputs!$C$21))*Inputs!$D$8)*(1-D$13))+(Inputs!$C$26*(((Inputs!$D$7*(1+Inputs!$C$21))*Inputs!$D$8)+Inputs!$D$16))-MIN(MAX(Inputs!$C$11-Inputs!$C$25,0),(((Inputs!$D$7*(1+Inputs!$C$21))*Inputs!$D$8)*(1-D$13))+(Inputs!$C$26*(((Inputs!$D$7*(1+Inputs!$C$21))*Inputs!$D$8)+Inputs!$D$16))))/(1-Inputs!$C$27))*Inputs!$C$23-MIN(MAX(Inputs!$C$11-Inputs!$C$25,0),(((Inputs!$D$7*(1+Inputs!$C$21))*Inputs!$D$8)*(1-D$13))+(Inputs!$C$26*(((Inputs!$D$7*(1+Inputs!$C$21))*Inputs!$D$8)+Inputs!$D$16)))*Inputs!$C$24-(Inputs!$C$29*(((Inputs!$D$7*(1+Inputs!$C$21))*Inputs!$D$8)-Inputs!$D$14))/Inputs!$C$30-(((((Inputs!$D$7*(1+Inputs!$C$21))*Inputs!$D$8)*(1-D$13))+(Inputs!$C$26*(((Inputs!$D$7*(1+Inputs!$C$21))*Inputs!$D$8)+Inputs!$D$16))-MIN(MAX(Inputs!$C$11-Inputs!$C$25,0),(((Inputs!$D$7*(1+Inputs!$C$21))*Inputs!$D$8)*(1-D$13))+(Inputs!$C$26*(((Inputs!$D$7*(1+Inputs!$C$21))*Inputs!$D$8)+Inputs!$D$16))))/(1-Inputs!$C$27))*Inputs!$C$27/Inputs!$C$28)*(1-Inputs!$C$32))/(Inputs!$C$8+(((Inputs!$D$7*(1+Inputs!$C$21))*Inputs!$D$8)*D$13/Inputs!$C$7))/(Inputs!$C$9*(1+Inputs!$C$33)^1)-1 -> 0.0068692474 | E16: =((Inputs!$C$9*(1+Inputs!$C$33)^1)*Inputs!$C$8+Inputs!$D$9*(1+Inputs!$C$34)^1*Inputs!$D$8+($B$16*Inputs!$D$35-(((((Inputs!$D$7*(1+Inputs!$C$21))*Inputs!$D$8)*(1-E$13))+(Inputs!$C$26*(((Inputs!$D$7*(1+Inputs!$C$21))*Inputs!$D$8)+Inputs!$D$16))-MIN(MAX(Inputs!$C$11-Inputs!$C$25,0),(((Inputs!$D$7*(1+Inputs!$C$21))*Inputs!$D$8)*(1-E$13))+(Inputs!$C$26*(((Inputs!$D$7*(1+Inputs!$C$21))*Inputs!$D$8)+Inputs!$D$16))))/(1-Inputs!$C$27))*Inputs!$C$23-MIN(MAX(Inputs!$C$11-Inputs!$C$25,0),(((Inputs!$D$7*(1+Inputs!$C$21))*Inputs!$D$8)*(1-E$13))+(Inputs!$C$26*(((Inputs!$D$7*(1+Inputs!$C$21))*Inputs!$D$8)+Inputs!$D$16)))*Inputs!$C$24-(Inputs!$C$29*(((Inputs!$D$7*(1+Inputs!$C$21))*Inputs!$D$8)-Inputs!$D$14))/Inputs!$C$30-(((((Inputs!$D$7*(1+Inputs!$C$21))*Inputs!$D$8)*(1-E$13))+(Inputs!$C$26*(((Inputs!$D$7*(1+Inputs!$C$21))*Inputs!$D$8)+Inputs!$D$16))-MIN(MAX(Inputs!$C$11-Inputs!$C$25,0),(((Inputs!$D$7*(1+Inputs!$C$21))*Inputs!$D$8)*(1-E$13))+(Inputs!$C$26*(((Inputs!$D$7*(1+Inputs!$C$21))*Inputs!$D$8)+Inputs!$D$16))))/(1-Inputs!$C$27))*Inputs!$C$27/Inputs!$C$28)*(1-Inputs!$C$32))/(Inputs!$C$8+(((Inputs!$D$7*(1+Inputs!$C$21))*Inputs!$D$8)*E$13/Inputs!$C$7))/(Inputs!$C$9*(1+Inputs!$C$33)^1)-1 -> 0.00034070098 | F16: =((Inputs!$C$9*(1+Inputs!$C$33)^1)*Inputs!$C$8+Inputs!$D$9*(1+Inputs!$C$34)^1*Inputs!$D$8+($B$16*Inputs!$D$35-(((((Inputs!$D$7*(1+Inputs!$C$21))*Inputs!$D$8)*(1-F$13))+(Inputs!$C$26*(((Inputs!$D$7*(1+Inputs!$C$21))*Inputs!$D$8)+Inputs!$D$16))-MIN(MAX(Inputs!$C$11-Inputs!$C$25,0),(((Inputs!$D$7*(1+Inputs!$C$21))*Inputs!$D$8)*(1-F$13))+(Inputs!$C$26*(((Inputs!$D$7*(1+Inputs!$C$21))*Inputs!$D$8)+Inputs!$D$16))))/(1-Inputs!$C$27))*Inputs!$C$23-MIN(MAX(Inputs!$C$11-Inputs!$C$25,0),(((Inputs!$D$7*(1+Inputs!$C$21))*Inputs!$D$8)*(1-F$13))+(Inputs!$C$26*(((Inputs!$D$7*(1+Inputs!$C$21))*Inputs!$D$8)+Inputs!$D$16)))*Inputs!$C$24-(Inputs!$C$29*(((Inputs!$D$7*(1+Inputs!$C$21))*Inputs!$D$8)-Inputs!$D$14))/Inputs!$C$30-(((((Inputs!$D$7*(1+Inputs!$C$21))*Inputs!$D$8)*(1-F$13))+(Inputs!$C$26*(((Inputs!$D$7*(1+Inputs!$C$21))*Inputs!$D$8)+Inputs!$D$16))-MIN(MAX(Inputs!$C$11-Inputs!$C$25,0),(((Inputs!$D$7*(1+Inputs!$C$21))*Inputs!$D$8)*(1-F$13))+(Inputs!$C$26*(((Inputs!$D$7*(1+Inputs!$C$21))*Inputs!$D$8)+Inputs!$D$16))))/(1-Inputs!$C$27))*Inputs!$C$27/Inputs!$C$28)*(1-Inputs!$C$32))/(Inputs!$C$8+(((Inputs!$D$7*(1+Inputs!$C$21))*Inputs!$D$8)*F$13/Inputs!$C$7))/(Inputs!$C$9*(1+Inputs!$C$33)^1)-1 -> -0.0055856177 | G16: =((Inputs!$C$9*(1+Inputs!$C$33)^1)*Inputs!$C$8+Inputs!$D$9*(1+Inputs!$C$34)^1*Inputs!$D$8+($B$16*Inputs!$D$35-(((((Inputs!$D$7*(1+Inputs!$C$21))*Inputs!$D$8)*(1-G$13))+(Inputs!$C$26*(((Inputs!$D$7*(1+Inputs!$C$21))*Inputs!$D$8)+Inputs!$D$16))-MIN(MAX(Inputs!$C$11-Inputs!$C$25,0),(((Inputs!$D$7*(1+Inputs!$C$21))*Inputs!$D$8)*(1-G$13))+(Inputs!$C$26*(((Inputs!$D$7*(1+Inputs!$C$21))*Inputs!$D$8)+Inputs!$D$16))))/(1-Inputs!$C$27))*Inputs!$C$23-MIN(MAX(Inputs!$C$11-Inputs!$C$25,0),(((Inputs!$D$7*(1+Inputs!$C$21))*Inputs!$D$8)*(1-G$13))+(Inputs!$C$26*(((Inputs!$D$7*(1+Inputs!$C$21))*Inputs!$D$8)+Inputs!$D$16)))*Inputs!$C$24-(Inputs!$C$29*(((Inputs!$D$7*(1+Inputs!$C$21))*Inputs!$D$8)-Inputs!$D$14))/Inputs!$C$30-(((((Inputs!$D$7*(1+Inputs!$C$21))*Inputs!$D$8)*(1-G$13))+(Inputs!$C$26*(((Inputs!$D$7*(1+Inputs!$C$21))*Inputs!$D$8)+Inputs!$D$16))-MIN(MAX(Inputs!$C$11-Inputs!$C$25,0),(((Inputs!$D$7*(1+Inputs!$C$21))*Inputs!$D$8)*(1-G$13))+(Inputs!$C$26*(((Inputs!$D$7*(1+Inputs!$C$21))*Inputs!$D$8)+Inputs!$D$16))))/(1-Inputs!$C$27))*Inputs!$C$27/Inputs!$C$28)*(1-Inputs!$C$32))/(Inputs!$C$8+(((Inputs!$D$7*(1+Inputs!$C$21))*Inputs!$D$8)*G$13/Inputs!$C$7))/(Inputs!$C$9*(1+Inputs!$C$33)^1)-1 -> -0.015460702
B17: 750 | C17: =((Inputs!$C$9*(1+Inputs!$C$33)^1)*Inputs!$C$8+Inputs!$D$9*(1+Inputs!$C$34)^1*Inputs!$D$8+($B$17*Inputs!$D$35-(((((Inputs!$D$7*(1+Inputs!$C$21))*Inputs!$D$8)*(1-C$13))+(Inputs!$C$26*(((Inputs!$D$7*(1+Inputs!$C$21))*Inputs!$D$8)+Inputs!$D$16))-MIN(MAX(Inputs!$C$11-Inputs!$C$25,0),(((Inputs!$D$7*(1+Inputs!$C$21))*Inputs!$D$8)*(1-C$13))+(Inputs!$C$26*(((Inputs!$D$7*(1+Inputs!$C$21))*Inputs!$D$8)+Inputs!$D$16))))/(1-Inputs!$C$27))*Inputs!$C$23-MIN(MAX(Inputs!$C$11-Inputs!$C$25,0),(((Inputs!$D$7*(1+Inputs!$C$21))*Inputs!$D$8)*(1-C$13))+(Inputs!$C$26*(((Inputs!$D$7*(1+Inputs!$C$21))*Inputs!$D$8)+Inputs!$D$16)))*Inputs!$C$24-(Inputs!$C$29*(((Inputs!$D$7*(1+Inputs!$C$21))*Inputs!$D$8)-Inputs!$D$14))/Inputs!$C$30-(((((Inputs!$D$7*(1+Inputs!$C$21))*Inputs!$D$8)*(1-C$13))+(Inputs!$C$26*(((Inputs!$D$7*(1+Inputs!$C$21))*Inputs!$D$8)+Inputs!$D$16))-MIN(MAX(Inputs!$C$11-Inputs!$C$25,0),(((Inputs!$D$7*(1+Inputs!$C$21))*Inputs!$D$8)*(1-C$13))+(Inputs!$C$26*(((Inputs!$D$7*(1+Inputs!$C$21))*Inputs!$D$8)+Inputs!$D$16))))/(1-Inputs!$C$27))*Inputs!$C$27/Inputs!$C$28)*(1-Inputs!$C$32))/(Inputs!$C$8+(((Inputs!$D$7*(1+Inputs!$C$21))*Inputs!$D$8)*C$13/Inputs!$C$7))/(Inputs!$C$9*(1+Inputs!$C$33)^1)-1 -> 0.040749553 | D17: =((Inputs!$C$9*(1+Inputs!$C$33)^1)*Inputs!$C$8+Inputs!$D$9*(1+Inputs!$C$34)^1*Inputs!$D$8+($B$17*Inputs!$D$35-(((((Inputs!$D$7*(1+Inputs!$C$21))*Inputs!$D$8)*(1-D$13))+(Inputs!$C$26*(((Inputs!$D$7*(1+Inputs!$C$21))*Inputs!$D$8)+Inputs!$D$16))-MIN(MAX(Inputs!$C$11-Inputs!$C$25,0),(((Inputs!$D$7*(1+Inputs!$C$21))*Inputs!$D$8)*(1-D$13))+(Inputs!$C$26*(((Inputs!$D$7*(1+Inputs!$C$21))*Inputs!$D$8)+Inputs!$D$16))))/(1-Inputs!$C$27))*Inputs!$C$23-MIN(MAX(Inputs!$C$11-Inputs!$C$25,0),(((Inputs!$D$7*(1+Inputs!$C$21))*Inputs!$D$8)*(1-D$13))+(Inputs!$C$26*(((Inputs!$D$7*(1+Inputs!$C$21))*Inputs!$D$8)+Inputs!$D$16)))*Inputs!$C$24-(Inputs!$C$29*(((Inputs!$D$7*(1+Inputs!$C$21))*Inputs!$D$8)-Inputs!$D$14))/Inputs!$C$30-(((((Inputs!$D$7*(1+Inputs!$C$21))*Inputs!$D$8)*(1-D$13))+(Inputs!$C$26*(((Inputs!$D$7*(1+Inputs!$C$21))*Inputs!$D$8)+Inputs!$D$16))-MIN(MAX(Inputs!$C$11-Inputs!$C$25,0),(((Inputs!$D$7*(1+Inputs!$C$21))*Inputs!$D$8)*(1-D$13))+(Inputs!$C$26*(((Inputs!$D$7*(1+Inputs!$C$21))*Inputs!$D$8)+Inputs!$D$16))))/(1-Inputs!$C$27))*Inputs!$C$27/Inputs!$C$28)*(1-Inputs!$C$32))/(Inputs!$C$8+(((Inputs!$D$7*(1+Inputs!$C$21))*Inputs!$D$8)*D$13/Inputs!$C$7))/(Inputs!$C$9*(1+Inputs!$C$33)^1)-1 -> 0.032167849 | E17: =((Inputs!$C$9*(1+Inputs!$C$33)^1)*Inputs!$C$8+Inputs!$D$9*(1+Inputs!$C$34)^1*Inputs!$D$8+($B$17*Inputs!$D$35-(((((Inputs!$D$7*(1+Inputs!$C$21))*Inputs!$D$8)*(1-E$13))+(Inputs!$C$26*(((Inputs!$D$7*(1+Inputs!$C$21))*Inputs!$D$8)+Inputs!$D$16))-MIN(MAX(Inputs!$C$11-Inputs!$C$25,0),(((Inputs!$D$7*(1+Inputs!$C$21))*Inputs!$D$8)*(1-E$13))+(Inputs!$C$26*(((Inputs!$D$7*(1+Inputs!$C$21))*Inputs!$D$8)+Inputs!$D$16))))/(1-Inputs!$C$27))*Inputs!$C$23-MIN(MAX(Inputs!$C$11-Inputs!$C$25,0),(((Inputs!$D$7*(1+Inputs!$C$21))*Inputs!$D$8)*(1-E$13))+(Inputs!$C$26*(((Inputs!$D$7*(1+Inputs!$C$21))*Inputs!$D$8)+Inputs!$D$16)))*Inputs!$C$24-(Inputs!$C$29*(((Inputs!$D$7*(1+Inputs!$C$21))*Inputs!$D$8)-Inputs!$D$14))/Inputs!$C$30-(((((Inputs!$D$7*(1+Inputs!$C$21))*Inputs!$D$8)*(1-E$13))+(Inputs!$C$26*(((Inputs!$D$7*(1+Inputs!$C$21))*Inputs!$D$8)+Inputs!$D$16))-MIN(MAX(Inputs!$C$11-Inputs!$C$25,0),(((Inputs!$D$7*(1+Inputs!$C$21))*Inputs!$D$8)*(1-E$13))+(Inputs!$C$26*(((Inputs!$D$7*(1+Inputs!$C$21))*Inputs!$D$8)+Inputs!$D$16))))/(1-Inputs!$C$27))*Inputs!$C$27/Inputs!$C$28)*(1-Inputs!$C$32))/(Inputs!$C$8+(((Inputs!$D$7*(1+Inputs!$C$21))*Inputs!$D$8)*E$13/Inputs!$C$7))/(Inputs!$C$9*(1+Inputs!$C$33)^1)-1 -> 0.024416044 | F17: =((Inputs!$C$9*(1+Inputs!$C$33)^1)*Inputs!$C$8+Inputs!$D$9*(1+Inputs!$C$34)^1*Inputs!$D$8+($B$17*Inputs!$D$35-(((((Inputs!$D$7*(1+Inputs!$C$21))*Inputs!$D$8)*(1-F$13))+(Inputs!$C$26*(((Inputs!$D$7*(1+Inputs!$C$21))*Inputs!$D$8)+Inputs!$D$16))-MIN(MAX(Inputs!$C$11-Inputs!$C$25,0),(((Inputs!$D$7*(1+Inputs!$C$21))*Inputs!$D$8)*(1-F$13))+(Inputs!$C$26*(((Inputs!$D$7*(1+Inputs!$C$21))*Inputs!$D$8)+Inputs!$D$16))))/(1-Inputs!$C$27))*Inputs!$C$23-MIN(MAX(Inputs!$C$11-Inputs!$C$25,0),(((Inputs!$D$7*(1+Inputs!$C$21))*Inputs!$D$8)*(1-F$13))+(Inputs!$C$26*(((Inputs!$D$7*(1+Inputs!$C$21))*Inputs!$D$8)+Inputs!$D$16)))*Inputs!$C$24-(Inputs!$C$29*(((Inputs!$D$7*(1+Inputs!$C$21))*Inputs!$D$8)-Inputs!$D$14))/Inputs!$C$30-(((((Inputs!$D$7*(1+Inputs!$C$21))*Inputs!$D$8)*(1-F$13))+(Inputs!$C$26*(((Inputs!$D$7*(1+Inputs!$C$21))*Inputs!$D$8)+Inputs!$D$16))-MIN(MAX(Inputs!$C$11-Inputs!$C$25,0),(((Inputs!$D$7*(1+Inputs!$C$21))*Inputs!$D$8)*(1-F$13))+(Inputs!$C$26*(((Inputs!$D$7*(1+Inputs!$C$21))*Inputs!$D$8)+Inputs!$D$16))))/(1-Inputs!$C$27))*Inputs!$C$27/Inputs!$C$28)*(1-Inputs!$C$32))/(Inputs!$C$8+(((Inputs!$D$7*(1+Inputs!$C$21))*Inputs!$D$8)*F$13/Inputs!$C$7))/(Inputs!$C$9*(1+Inputs!$C$33)^1)-1 -> 0.017379307 | G17: =((Inputs!$C$9*(1+Inputs!$C$33)^1)*Inputs!$C$8+Inputs!$D$9*(1+Inputs!$C$34)^1*Inputs!$D$8+($B$17*Inputs!$D$35-(((((Inputs!$D$7*(1+Inputs!$C$21))*Inputs!$D$8)*(1-G$13))+(Inputs!$C$26*(((Inputs!$D$7*(1+Inputs!$C$21))*Inputs!$D$8)+Inputs!$D$16))-MIN(MAX(Inputs!$C$11-Inputs!$C$25,0),(((Inputs!$D$7*(1+Inputs!$C$21))*Inputs!$D$8)*(1-G$13))+(Inputs!$C$26*(((Inputs!$D$7*(1+Inputs!$C$21))*Inputs!$D$8)+Inputs!$D$16))))/(1-Inputs!$C$27))*Inputs!$C$23-MIN(MAX(Inputs!$C$11-Inputs!$C$25,0),(((Inputs!$D$7*(1+Inputs!$C$21))*Inputs!$D$8)*(1-G$13))+(Inputs!$C$26*(((Inputs!$D$7*(1+Inputs!$C$21))*Inputs!$D$8)+Inputs!$D$16)))*Inputs!$C$24-(Inputs!$C$29*(((Inputs!$D$7*(1+Inputs!$C$21))*Inputs!$D$8)-Inputs!$D$14))/Inputs!$C$30-(((((Inputs!$D$7*(1+Inputs!$C$21))*Inputs!$D$8)*(1-G$13))+(Inputs!$C$26*(((Inputs!$D$7*(1+Inputs!$C$21))*Inputs!$D$8)+Inputs!$D$16))-MIN(MAX(Inputs!$C$11-Inputs!$C$25,0),(((Inputs!$D$7*(1+Inputs!$C$21))*Inputs!$D$8)*(1-G$13))+(Inputs!$C$26*(((Inputs!$D$7*(1+Inputs!$C$21))*Inputs!$D$8)+Inputs!$D$16))))/(1-Inputs!$C$27))*Inputs!$C$27/Inputs!$C$28)*(1-Inputs!$C$32))/(Inputs!$C$8+(((Inputs!$D$7*(1+Inputs!$C$21))*Inputs!$D$8)*G$13/Inputs!$C$7))/(Inputs!$C$9*(1+Inputs!$C$33)^1)-1 -> 0.0064917182
